Workbook

Sheet 1. Materie prime e prodotti
E7: gen | F7: feb | G7: mar | H7: apr | I7: mag | J7: giu | K7: lug | L7: ago | M7: set | N7: ott | O7: nov | P7: dic | Q7: ANNO
B8: Materie prime | C8: Grano Duro e Tenero | D8: (t) | E8: 10474 | F8: 5276 | G8: 4428 | H8: 5601 | I8: 7848 | J8: 7131 | K8: 8371 | L8: 3644 | M8: 8100 | N8: 7408 | O8: 9181 | P8: 7336 | Q8: =SUM(E8:P8) -> 84798
B9: Addittivi e ausiliari di processo | C9: Altri ingredienti | D9: (Kg) | E9: 0 | F9: 0 | G9: 0 | H9: 0 | I9: 0 | J9: 0 | K9: 0 | L9: 0 | M9: 0 | N9: 0 | O9: 0 | P9: 0 | Q9: =SUM(E9:P9) -> 0
C10: Imballaggi - Sacchi per confezionamento | D10: (t) | E10: 4.185 | F10: 0 | G10: 15.89 | H10: 0 | I10: 0 | J10: 17.43 | K10: 11.04 | L10: 29.73 | M10: 13.86 | N10: 9.27 | O10: 9.41 | P10: 7.23 | Q10: =SUM(E10:P10) -> 118.045
C11: Imballaggi - Film estensibile per confezionamento | D11: (t) | E11: 0 | F11: 0 | G11: 3.08 | H11: 0 | I11: 3.058 | J11: 0 | K11: 0 | L11: 4.627 | M11: 0 | N11: 0 | O11: 0 | P11: 4.665 | Q11: =SUM(E11:P11) -> 15.43
B12: Prodotto finito | C12: Semola di grano duro | D12: (t) | E12: 4893 | F12: 1555 | G12: 1539 | H12: 1520 | I12: 1921 | J12: 2634 | K12: 1131 | L12: 815 | M12: 2375 | N12: 2652 | O12: 3456 | P12: 2905 | Q12: =SUM(E12:P12) -> 27396
C13: Farina di frano tenero | D13: (t) | E13: 3327 | F13: 2533 | G13: 1849 | H13: 2814 | I13: 4047 | J13: 2887 | K13: 4264 | L13: 1847 | M13: 3779 | N13: 3059 | O13: 3633 | P13: 2943 | Q13: =SUM(E13:P13) -> 36982
B14: Coprodotti | C14: Cruscami | D14: (t) | E14: 2528 | F14: 1333 | G14: 1156 | H14: 1407 | I14: 2136 | J14: 1841 | K14: 2244 | L14: 1060 | M14: 2061 | N14: 1927 | O14: 3432 | P14: 1722 | Q14: =SUM(E14:P14) -> 22847

Sheet 2. Sistema idrico
D3: Matricola | E3: Codice | F3: u.m. | G3: gen | H3: feb | I3: mar | J3: apr | K3: mag | L3: giu | M3: lug | N3: ago | O3: set | P3: ott | Q3: nov | R3: dic | S3: ANNO
B4: Consumi idrici | C4: acquedotto - servizi igienico sanitari | D4: 2016184064 | E4: 757977192 | F4: (m3) | G4: 128 | H4: 83 | I4: 81 | J4: 108 | K4: 119 | L4: 131 | M4: 122 | N4: 93 | O4: 136 | P4: 132 | Q4: 151 | R4: 75 | S4: =SUM(G4:R4) -> 1359
C5: acquedotto industriale - ciclo produttivo | D5: 2016184313 | E5: 757978205 | F5: (m3) | G5: 821 | H5: 413 | I5: 483 | J5: 485 | K5: 507 | L5: 559 | M5: 1350 | N5: 353 | O5: 820 | P5: 673 | Q5: 696 | R5: 608 | S5: =SUM(G5:R5) -> 7768
C6: acquedotto - impianto antincendio | D6: 2016184334 | E6: 763072702 | F6: (m3) | G6: 65 | H6: 0 | I6: 0 | J6: 0 | K6: 0 | L6: 49 | M6: 251 | N6: 0 | O6: 0 | P6: 0 | Q6: 0 | R6: 0 | S6: =SUM(G6:R6) -> 365
B8: bilancio idrico ciclo produttivo
B9: Flusso (rif. acquedotto industriale) | C9: Valore (t/anno) | D9: Riferimento alle registrazioni o altri documenti del SG Eventuali calcoli
B10: F consumo di acqua | C10: 7768
B11: WP fabbisogno idrico complessivo | C11: 7768
B12: E acqua evaporata | C12: n.d.
B13: W1 acque reflue prodotte | C13: 0
B14: W acque reflue destinate allo scarico | C14: 0
B15: R acque reflue riciclate | C15: 0

Sheet 3. Scarichi idrici
H2: N° Ordine | I2: 379093 | K2: 381109 | M2: 379077
H3: N° Campione | I3: 265652 | K3: 269747 | M3: 269735
H4: Data prelievo campione | I4: 45533 | K4: 12.09.2024 | M4: 12.09.2024
D5: Parametro | E5: Frequenza | F5: U.M. | G5: Valori limite da D.lgs 152/06 | H5: Metodo | I5: Risultato | J5: Incertezza | K5: Risultato | L5: Incertezza | M5: Risultato | N5: Incertezza
B6: Scarico S1 | C6: Reflui domestici dalla palazzina uffici e dall'area spogliatoi/infermeria | D6: pH (in campo) | E6: Annuale | F6: upH | G6: 5,5 - 9.5 | H6: APAT CNR IRSA 2060 Man 29 2003 | M6: 7.95 | N6: +/- 0,16
D7: Solidi sospesi totali | E7: Annuale | F7: mg/l | G7: 80 | H7: APAT CNR IRSA 2090 B Man 29 2003 | M7: 370 | N7: +/- 37
D8: Materiali sedimentabili | E8: Annuale | F8: ml/l | G8: / | H8: APAT CNR IRSA 2090 C Man 29 2003 | M8: 6.2 | N8: +/- 0,62
D9: BOD5 | E9: Annuale | F9: mg/l | G9: 40 | H9: UNI EN ISO 5815-1:2019 + ISO 17289:2014 | M9: 10.6 | N9: +/- 3,7
D10: COD - Richiesta chimica di ossigeno | E10: Annuale | F10: mg/l | G10: 160 | H10: ISO 15705:2002 | M10: 29 | N10: +/- 11
D11: Cloruri | E11: Annuale | F11: mg/l | G11: 1200 | H11: APAT CNR IRSA 4020 Man 29 2003 | M11: 27.4 | N11: +/- 8,2
D12: Fosforo totale (come P) | E12: Annuale | F12: mg/l | G12: 10 | H12: EPA 200.7 1994 | M12: 1.49 | N12: +/- 0,22
D13: Azoto ammoniacale (come NH4) | E13: Annuale | F13: mg/l | G13: 15 | H13: UNI 11669:2017 | M13: 11 | N13: +/- 1,7
D14: Azoto nitroso (come N) | E14: Annuale | F14: mg/l | G14: 0.6 | H14: APAT CNR IRSA 4020 Man 29 2003 | M14: 0.96 | N14: +/- 0,29
D15: Azoto nitrico (come N) | E15: Annuale | F15: mg/l | G15: 20 | H15: APAT CNR IRSA 4020 Man 29 2003 | M15: 0.51 | N15: +/- 0,20
D16: Sommatoria tensioattivi | E16: Annuale | F16: mg/l | G16: 2 | H16: APAT CNR IRSA 5170+ 5180 MAN 29/2003 | M16: <0,150 | N16: /
D17: Tensioattivi non ionici etossilati | E17: Annuale | F17: mg/l | G17: / | H17: APAT CNR IRSA 5180 MAN 29/2003 | M17: <0,0500 | N17: /
D18: Tensioattivi anionici | E18: Annuale | F18: mg/l | G18: / | H18: APAT CNR IRSA 5170 MAN 29/2003 | M18: <0,0500 | N18: /
D19: Tensioattivi cationici | E19: Annuale | F19: mg/l | G19: / | H19: MP-02258-IT2020 REV02 | M19: <0,2 | N19: /
D20: Conta E.coli | E20: Mensile (dal 1° Aprile al 30 settembre | F20: ufc/100ml | G20: 5.000 UFC/100 ml (consigliato) | H20: APAT CNR IRSA 7030 D MAN 29/2003 | I20: 250 | J20: / | K20: 6500 | L20: /
H22: N° Ordine | I22: 379093 | K22: 381109 | M22: 379077
H23: N° Campione | I23: 265653 | K23: 269748 | M23: 269736
H24: Data prelievo campione | I24: 45533 | K24: 45547 | M24: 45547
D25: Parametro | E25: Frequenza | F25: U.M. | G25: Valori limite da D.lgs 152/06 | H25: Metodo | I25: Risultato | J25: Incertezza | K25: Risultato | L25: Incertezza | M25: Risultato | N25: Incertezza
B26: Scarico S2 | C26: Scarico Reflui domestici locali laboratorio e servizi igienici della zona di insacco | D26: pH (in campo) | E26: Annuale | F26: upH | G26: 5,5 - 9.5 | H26: APAT CNR IRSA 2060 Man 29 2003 | M26: 7.89 | N26: +/- 0,16
D27: Solidi sospesi totali | E27: Annuale | F27: mg/l | G27: 80 | H27: APAT CNR IRSA 2090 B Man 29 2003 | M27: 22 | N27: +/- 8,8
D28: Materiali sedimentabili | E28: Annuale | F28: ml/l | G28: / | H28: APAT CNR IRSA 2090 C Man 29 2003 | M28: 1.3 | N28: +/- 0,13
D29: BOD5 | E29: Annuale | F29: mg/l | G29: 40 | H29: UNI EN ISO 5815-1:2019 + ISO 17289:2014 | M29: 5.1 | N29: +/- 1,8
D30: COD - Richiesta chimica di ossigeno | E30: Annuale | F30: mg/l | G30: 160 | H30: ISO 15705:2002 | M30: 30.7 | N30: +/- 9,2
D31: Cloruri | E31: Annuale | F31: mg/l | G31: 1200 | H31: APAT CNR IRSA 4020 Man 29 2003 | M31: 15.6 | N31: +/- 6,3
D32: Fosforo totale (come P) | E32: Annuale | F32: mg/l | G32: 10 | H32: EPA 200.7 1994 | M32: 0.97 | N32: +/- 0,14
D33: Azoto ammoniacale (come NH4) | E33: Annuale | F33: mg/l | G33: 15 | H33: UNI 11669:2017 | M33: 0.194 | N33: +/- 0,048
D34: Azoto nitroso (come N) | E34: Annuale | F34: mg/l | G34: 0.6 | H34: APAT CNR IRSA 4020 Man 29 2003 | M34: 0.054 | N34: +/- 0,022
D35: Azoto nitrico (come N) | E35: Annuale | F35: mg/l | G35: 20 | H35: APAT CNR IRSA 4020 Man 29 2003 | M35: 0.99 | N35: +/- 0,040
D36: Sommatoria tensioattivi | E36: Annuale | F36: mg/l | G36: 2 | H36: APAT CNR IRSA 5170+ 5180 MAN 29/2003 | M36: <0,150 | N36: /
D37: Tensioattivi non ionici etossilati | E37: Annuale | F37: mg/l | G37: / | H37: APAT CNR IRSA 5180 MAN 29/2003 | M37: <0,05 | N37: /
D38: Tensioattivi anionici | E38: Annuale | F38: mg/l | G38: / | H38: APAT CNR IRSA 5170 MAN 29/2003 | M38: <0,0500 | N38: /
D39: Tensioattivi cationici | E39: Annuale | F39: mg/l | G39: / | H39: MP-02258-IT2020 REV02 | M39: <0,200 | N39: /
D40: Conta E.coli | E40: Mensile (dal 1° Aprile al 30 settembre | F40: ufc/100ml | G40: 5.000 UFC/100 ml (consigliato) | H40: APAT CNR IRSA 7030 D MAN 29/2003 | I40: 6700 | J40: / | K40: 16000 | L40: /

Sheet 4. Sistema energetico
B1: ANNO 2024
B3: LIVORNO | J3: FOTOVOLTAICO
B4: Mese | C4: kWh F1 | D4: %F1 | E4: kWh F2 | F4: %F2 | G4: kWh F3 | H4: %F3 | I4: Totale kWh | J4: kWh prodotti
B5: Gennaio | C5: 489300 | D5: =C5/I5 -> 0.46355903 | E5: 233562 | F5: =E5/I5 -> 0.22127483 | G5: 332667 | H5: =G5/I5 -> 0.31516614 | I5: =C5+E5+G5 -> 1055529 | J5: 6336
B6: Febbraio | C6: 355317 | D6: =C6/I6 -> 0.52252884 | E6: 136791 | F6: =E6/I6 -> 0.20116471 | G6: 187887 | H6: =G6/I6 -> 0.27630644 | I6: =C6+E6+G6 -> 679995 | J6: 6621
B7: Marzo | C7: 354237 | D7: =C7/I7 -> 0.58243601 | E7: 119655 | F7: =E7/I7 -> 0.19673659 | G7: 134307 | H7: =G7/I7 -> 0.22082739 | I7: =C7+E7+G7 -> 608199 | J7: 9288
B8: Aprile | C8: 369363 | D8: =C8/I8 -> 0.55053457 | E8: 126537 | F8: =E8/I8 -> 0.18860306 | G8: 175017 | H8: =G8/I8 -> 0.26086237 | I8: =C8+E8+G8 -> 670917 | J8: 13540
B9: Maggio | C9: 429432 | D9: =C9/I9 -> 0.50545019 | E9: 180861 | F9: =E9/I9 -> 0.21287707 | G9: 239310 | H9: =G9/I9 -> 0.28167273 | I9: =C9+E9+G9 -> 849603 | J9: 14567
B10: Giugno | C10: 416349 | D10: =C10/I10 -> 0.53109059 | E10: 162009 | F10: =E10/I10 -> 0.20665705 | G10: 205593 | H10: =G10/I10 -> 0.26225236 | I10: =C10+E10+G10 -> 783951 | J10: 15088
B11: Luglio | C11: 476214 | D11: =C11/I11 -> 0.51386987 | E11: 201078 | F11: =E11/I11 -> 0.21697793 | G11: 249429 | H11: =G11/I11 -> 0.2691522 | I11: =C11+E11+G11 -> 926721 | J11: 13818
B12: Agosto | C12: 236058 | D12: =C12/I12 -> 0.45128211 | E12: 132816 | F12: =E12/I12 -> 0.25390999 | G12: 154209 | H12: =G12/I12 -> 0.2948079 | I12: =C12+E12+G12 -> 523083 | J12: 9298
B13: Settembre | C13: 448389 | D13: =C13/I13 -> 0.49057824 | E13: 199503 | F13: =E13/I13 -> 0.21827438 | G13: 266109 | H13: =G13/I13 -> 0.29114738 | I13: =C13+E13+G13 -> 914001 | J13: 10235
B14: Ottobre | C14: 449028 | D14: =C14/I14 -> 0.53091281 | E14: 174771 | F14: =E14/I14 -> 0.20664226 | G14: 221967 | H14: =G14/I14 -> 0.26244493 | I14: =C14+E14+G14 -> 845766 | J14: 5767
B15: Novembre | C15: 481089 | D15: =C15/I15 -> 0.4993492 | E15: 202215 | F15: =E15/I15 -> 0.20989027 | G15: 280128 | H15: =G15/I15 -> 0.29076053 | I15: =C15+E15+G15 -> 963432 | J15: 7009
B16: Dicembre | C16: 415566 | D16: =C16/I16 -> 0.51340002 | E16: 171279 | F16: =E16/I16 -> 0.21160211 | G16: 222594 | H16: =G16/I16 -> 0.27499787 | I16: =C16+E16+G16 -> 809439 | J16: 4866
B17: Complessivo | C17: =SUM(C5:C16) -> 4920342 | D17: =C17/I17 -> 0.5109052 | E17: =SUM(E5:E16) -> 2041077 | F17: =E17/I17 -> 0.21193585 | G17: =SUM(G5:G16) -> 2669217 | H17: =G17/I17 -> 0.27715895 | I17: =SUM(I5:I16) -> 9630636 | J17: =SUM(J5:J16) -> 116433
B21: GAS metano consumato (m3): | D21: 19022

Sheet 5. Rifiuti prodotti
B2: Codice CER | C2: Destinazione | D2: Quantità | E2: U.M. | F2: Frequenza rilevamento | G2: Modalità rilevamento | H2: Giacenza al 31/12/23 | I2: Giacenza al 31/12/24 | J2: Descrizione CER | K2: Tipologia | L2: TE | M2: DR | N2: Quantità
B3: Codifica | C3: Smaltimento e/o recupero | D3: Quantitativo | E3: t | F3: Ogni conferimento | G3: Quantità rilevate e confermate dal destinatario (4° copia formulario) | H3: t | I3: t | J3: Definizione rifiuto | K3: PERICOLOSO / NON PERICOLOSO | L3: SOGGETTO TRASPORTATORE | M3: SOGGETTO GESTORE IMPIANTO DI TRATTAMENTO | N3: t
B4: 02 03 04 | C4: Recupero - R13 | D4: 31.22 | E4: t | F4: SI | G4: 31.22 | H4: 0 | I4: 0 | J4: Scarti inutilizzabili per il consumo o la trasformazione | K4: NON PERICOLOSO | L4: T.LOG & CO S.r.l. | M4: PADANA RECUPERI | N4: 31.22
B5: 15 01 01 | C5: Recupero - R13-R12 | D5: 11.74 | E5: t | F5: SI | G5: 11.74 | H5: 0 | I5: 0 | J5: Imballaggi di carta e cartone | K5: NON PERICOLOSO | L5: T.LOG & CO S.r.l. | M5: REAL S.r.l. | N5: 11.74
B6: 15 01 02 | C6: Recupero -.R13 | D6: 2.01 | E6: t | F6: SI | G6: 2.01 | H6: 0 | I6: 0 | J6: Imballaggi di plastica | K6: NON PERICOLOSO | L6: T.LOG & CO S.r.l. | M6: ECOVALDIPERGA S.R.L.S. | N6: 1.33
M7: LIVORNO ECO-LOGISTIC SRL | N7: 0.68
B8: 15 01 03 | C8: Recupero - R12 | D8: 1.52 | E8: t | F8: SI | G8: 1.52 | H8: 0 | I8: 0 | J8: Imballaggi in legno | K8: NON PERICOLOSO | L8: T.LOG & CO S.r.l. | M8: BOGI VINICIO SRL | N8: 1.52
B9: 15 01 10 | C9: Recupero - R13 | D9: 0.377 | E9: t | F9: SI | G9: 0.377 | H9: 0 | I9: 0 | J9: Imballaggi contenenti residui di sostanze pericolose o contaminati da tali sostanze | K9: PERICOLOSO | L9: T.LOG & CO S.r.l. | M9: ECOVIP | N9: 0.377
B10: 15 01 11 | C10: Recupero - R13 | D10: 0.063 | E10: t | F10: SI | G10: 0.063 | H10: 0 | I10: 0 | J10: Imballaggi metallici contenenti matrici solide porose pericolose (ad esempio amianto), compresi i contenitori a pressione vuoti. | K10: PERICOLOSO | L10: T.LOG & CO S.r.l. | M10: ECOVIP | N10: 0.063
B11: 15 02 03 | C11: Recupero - R13 | D11: 0.56 | E11: t | F11: SI | G11: 0.56 | H11: 0 | I11: 0 | J11: Assorbenti, materiali filtranti, stracci e indumenti protettivi, diversi da quelli di cui alla voce 15 02 02 | K11: NON PERICOLOSO | L11: T.LOG & CO S.r.l. | M11: ECOS S.R.L. | N11: 0.56
B12: 17 02 03 | C12: Recupero - R12 | D12: 0.5 | E12: t | F12: SI | G12: 0.64 | H12: 0.4 | I12: 0.26 | J12: Plastica | K12: NON PERICOLOSO | L12: T.LOG & CO S.r.l. | M12: ECOVIP | N12: 0.64
B13: 17 04 05 | C13: Recupero - R13 | D13: 8.62 | E13: t | F13: SI | G13: 8.62 | H13: 0 | I13: 0 | J13: Ferro e acciaio | K13: NON PERICOLOSO | L13: PIERINI LUCA | M13: ECORICICLI S.r.l. | N13: 5.7
M14: BOGI VINICIO SRL | N14: 2.92
B15: 20 01 21 | C15: / | D15: 0.1 | E15: t | F15: SI | G15: / | H15: 0 | I15: 0.1 | J15: Tubi fluorescenti ed altri rifiuti conteneti mercurio | K15: PERICOLOSO | L15: / | M15: / | N15: /
B18: Rifiuti | C18: Destinazione | D18: Quantità (t) | E18: Produzione Percentuale su Totale Tipologia Rifiuto (pericoloso - non pericoloso) | G18: Produzione Specifica (Kg/t di prodotto) | H18: Note
B19: Rifiuti Pericolosi | C19: Recupero | D19: =D9+D10+D15 -> 0.54 | E19: =(D19*100)/(D9+D10+D15) -> 100 | G19: =((D9+D10+D15)*1000)/('1. Materie prime e prodotti'!Q12+'1. Materie prime e prodotti'!Q13+'1. Materie prime e prodotti'!Q14) -> 0.0061908856
B20: Rifiuti Pericolosi | C20: Smaltimento | D20: 0 | E20: =(D20*100)/(D9+D10+D15) -> 0 | G20: =D20/('1. Materie prime e prodotti'!Q12+'1. Materie prime e prodotti'!Q13+'1. Materie prime e prodotti'!Q14) -> 0
B21: Rifiuti non Pericolosi | C21: Recupero | D21: =D4+D5+D6+D8+D11+D12+D13 -> 56.17 | E21: =(D21*100)/(D4+D5+D6+D8+D11+D12+D13) -> 100 | G21: =(D21*1000)/('1. Materie prime e prodotti'!Q12+'1. Materie prime e prodotti'!Q13+'1. Materie prime e prodotti'!Q14) -> 0.64396675
B22: Rifiuti non Pericolosi | C22: Smaltimento | D22: 0 | E22: =(D22*100)/(D4+D5+D6+D8+D11+D12+D13) -> 0 | G22: =D22/('1. Materie prime e prodotti'!Q12+'1. Materie prime e prodotti'!Q13+'1. Materie prime e prodotti'!Q14) -> 0
B23: Rifiuti totali | C23: Recupero | D23: =D4+D5+D6+D8+D9+D10+D11+D12+D13+D15 -> 56.71 | E23: =(D23*100)/(D4+D5+D6+D8+D9+D10+D11+D12+D13+D15) -> 100 | G23: =(D23*1000)/('1. Materie prime e prodotti'!Q12+'1. Materie prime e prodotti'!Q13+'1. Materie prime e prodotti'!Q14) -> 0.65015764
B24: Rifiuti totali | C24: Smaltimento | D24: 0 | E24: =(D24*100)/(D4+D5+D6+D8+D9+D10+D11+D12+D13+D15) -> 0 | G24: =D24/('1. Materie prime e prodotti'!Q12+'1. Materie prime e prodotti'!Q13+'1. Materie prime e prodotti'!Q14) -> 0

Sheet 6. Emissioni Atmosfera
A1: Sigla | B1: Unità di appartenenza | C1: Fase di Processo | D1: Origine | E1: Parametro | F1: Modalità di controllo | G1: Frequenza | H1: Portata Nm3/h | I1: Concentrazione limite mg/Nm3 | J1: Inquinanti emessi mg/Nm3 | K1: Rapporti di Prova n° | L1: Velocità m/s | M1: Temp fumi °C | N1: Umidità % v/v | O1: Portata Fumi Secchi Nmc/h | P1: Flusso di massa g/h
A2: E1 | B2: Scarico nave | C2: TRASPORTO | D2: trasportatore torre | E2: polvere di grano | F2: discontinuo | G2: Annuale | H2: 4800 | I2: 5 | J2: 0.3622 | K2: 390991-309329,330,331 | L2: 11.45 | M2: 15.23 | N2: 2 | O2: 4843.3 | P2: 1.754
A3: E2 | B3: Scarico nave | C3: TRASPORTO | D3: nastro in banchina | E3: polvere di grano | F3: discontinuo | G3: Annuale | H3: 4800 | I3: 5 | J3: 0.361 | K3: 390992-309392,333,334 | L3: 11.49 | M3: 15.77 | N3: 2 | O3: 4846.7 | P3: 1.75
A4: E3 | B4: Scarico nave | C4: TRASPORTO | D4: trasportatore | E4: polvere di grano | F4: discontinuo | G4: Annuale | H4: 4200 | I4: 5 | J4: 0.2688 | K4: 390999-309335,336,337 | L4: 15.33 | M4: 16.23 | N4: 2 | O4: 4133.3 | P4: 1.111
A5: E4 | B5: Prepulitura lato mare | C5: PREPULITURA | D5: aspiraz. generale | E5: polvere di grano | F5: discontinuo | G5: Annuale | H5: 13200 | I5: 5 | J5: 0.3542 | K5: 391008-309342,343,344 | L5: 16.783 | M5: 16.17 | N5: 2 | O5: 12883.3 | P5: 4.563
A6: E5 | B6: Prepulitura lato mare | C6: PREPULITURA | D6: vibroblok | E6: polvere di grano | F6: discontinuo | G6: Annuale | H6: 10800 | I6: 5 | J6: 0.375 | K6: 391010-309346,347,348 | L6: 11.043 | M6: 16.57 | N6: 2 | O6: 10453.3 | P6: 3.92
A7: E6 | B7: Prepulitura lato mare | C7: PREPULITURA | D7: vibroblok | E7: polvere di grano | F7: discontinuo | G7: Annuale | H7: 10800 | I7: 5 | J7: 0.3065 | K7: 391013-309352,353,354 | L7: 13.57 | M7: 16.37 | N7: 2 | O7: 10406.7 | P7: 3.19
A8: E7 | B8: Trasferimento grano | C8: TRASPORTO | D8: trasportatore | E8: polvere di grano | F8: discontinuo | G8: Annuale | H8: 4200 | I8: 5 | J8: 0.2745 | K8: 391016-308095,096,097 | L8: 14.56 | M8: 7.33 | N8: 2 | O8: 4023.3 | P8: 1.104
A9: E8 | B9: Trasferimento grano | C9: TRASPORTO | D9: trasportatore | E9: polvere di grano | F9: discontinuo | G9: Annuale | H9: 4200 | I9: 5 | J9: 0.2773 | K9: 391019-308107,108,109 | L9: 14.45 | M9: 7.3 | N9: 2 | O9: 3990 | P9: 1.106
A10: E9 | B10: Prepulitura lato terra T | C10: PREPULITURA | D10: bilancia | E10: polvere di grano | F10: discontinuo | G10: Annuale | H10: 3600 | I10: 5 | J10: 0.3567 | K10: 391022-308071,072,073 | L10: 11.14 | M10: 7.2 | N10: 2 | O10: 3526.7 | P10: 1.258
A11: E10 | B11: Prepulitura lato terra T | C11: PREPULITURA | D11: vibroblok | E11: polvere di grano | F11: discontinuo | G11: Annuale | H11: 10800 | I11: 5 | J11: 0.372 | K11: 391023-308079,080,081 | L11: 10.633 | M11: 7.13 | N11: 2 | O11: 10483.3 | P11: 3.9
A12: E11 | B12: Prepulitura lato terra D | C12: PREPULITURA | D12: bilancia | E12: polvere di grano | F12: discontinuo | G12: Annuale | H12: 3600 | I12: 5 | J12: 0.3562 | K12: 391026-308060,061,062 | L12: 11.17 | M12: 6.9 | N12: 2 | O12: 3533.3 | P12: 1.259
A13: E12 | B13: Prepulitura lato terra D | C13: PREPULITURA | D13: vibroblok | E13: polvere di grano | F13: discontinuo | G13: Annuale | H13: 10800 | I13: 5 | J13: 0.3688 | K13: 391029-308045,046,047 | L13: 10.67 | M13: 6.73 | N13: 2 | O13: 10536.7 | P13: 3.886
... A91: E97 | B91: Manutenzione | C91: MANUTENZIONE | D91: Asp. Saldatura | E91: Polvere | F91: discontinuo | G91: Unica | H91: 6400 | I91: 5 | J91: 0.359 | K91: 393862-306863,864,865 | L91: 26.1 | M91: 17.9 | N91: 2 | O91: 6116.7 | P91: 2.196
E92: Cr | I92: 0.1 | J92: 0.004 | P92: 0.02447
E93: Ni | I93: 0.1 | J93: 0.000897 | P93: 0.005487
E94: Cd | I94: 0.1 | J94: 0.00045 | P94: 0.002753
E95: Co | I95: 0.1 | J95: 0.000897 | P95: 0.005487
E96: Pb | I96: 0.1 | J96: 0.000897 | P96: 0.005487
E97: Sn | I97: 2 | J97: 0.0897 | P97: 0.5487
A98: E112 | B98: Miscelazione | C98: MOVIMENTAZIONE | D98: Ripasso Farine | E98: polvere di farina | F98: discontinuo | G98: Annuale | H98: / | I98: 5 | J98: 0.5 | K98: 371501-250997,998,999 | L98: 23.3 | M98: 27.1 | N98: 2 | O98: 590.2 | P98: 0.0002951
A99: E113 | B99: Miscelazione | C99: MOVIMENTAZIONE | D99: Insacco Germe | E99: polvere di farina | F99: discontinuo | G99: Annuale | H99: / | I99: 5 | J99: 0.5 | K99: 371502-251001,002,003 | L99: 7.7 | M99: 31.23 | N99: 2 | O99: 3303 | P99: 0.001652

Sheet 7. Emissioni sonore
B3: MISURE A CONFINE DELLO STABILIMENTO
B4: Punto di misura | C4: Data | D4: Tempo di misura | E4: Leq dB(A) | F4: Leq dB(A) arrotondato | G4: Correzione per componente impulsiva Ki (dB) | H4: Correzione per componente tonale | J4: La corretto dB(A) | K4: Valore limite di emissione
H5: KT (dB) | I5: KB (dB)
B6: P1 1^ misura | C6: 45602 | D6: 1108 ÷1140 | E6: 59.1 | F6: 59 | G6: -- | H6: -- | I6: -- | J6: 59 | K6: 65
B7: P1 2^ misura | C7: 45631 | D7: 1603 ÷1633 | E7: 60.2 | F7: 60 | G7: -- | H7: -- | I7: -- | J7: 60
B8: P2 1^ misura | C8: 45602 | D8: 1037 ÷1107 | E8: 61.3 | F8: 61.5 | G8: -- | H8: -- | I8: -- | J8: 61.5
B9: P2 2^ misura | C9: 45631 | D9: 1531 ÷1601 | E9: 53.5 | F9: 53.5 | G9: -- | H9: -- | I9: -- | J9: 53.5
B10: P2-bis 1^ misura | C10: 45631 | D10: 1147 ÷1218 | E10: 62 | F10: 62 | G10: -- | H10: -- | I10: -- | J10: 62
B11: P2-bis 2^ misura | C11: 45631 | D11: 1459 ÷1529 | E11: 50.4 | F11: 50.5 | G11: -- | H11: -- | I11: -- | J11: 50.5
B12: P3 1^ misura | C12: 45631 | D12: 946 ÷1017 | E12: 60.8 | F12: 61 | G12: -- | H12: -- | I12: -- | J12: 61
B13: P3 2^ misura | C13: 45631 | D13: 1322 ÷1352 | E13: 54.3 | F13: 54.5 | G13: -- | H13: -- | I13: -- | J13: 54.5
B14: P4 1^ misura | C14: 45602 | D14: 1448 ÷1518 | E14: 57.4 | F14: 57.5 | G14: -- | H14: -- | I14: -- | J14: 57.5
B15: P4 2^ misura | C15: 45631 | D15: 915 ÷945 | E15: 60.1 | F15: 60 | G15: -- | H15: -- | I15: -- | J15: 60
B16: P5 1^ misura | C16: 45631 | D16: 1037 ÷1109 | E16: 60.6 | F16: 60.5 | G16: -- | H16: -- | I16: -- | J16: 60.5
B17: P5 2^ misura | C17: 45631 | D17: 1356 ÷1426 | E17: 59.5 | F17: 59.5 | G17: -- | H17: -- | I17: -- | J17: 59.5
B18: P6 1^ misura | C18: 45631 | D18: 1114 ÷1145 | E18: 61.1 | F18: 61 | G18: -- | H18: -- | I18: -- | J18: 61
B19: P6 2^ misura | C19: 45631 | D19: 1428 ÷1458 | E19: 52.3 | F19: 52.5 | G19: -- | H19: -- | I19: -- | J19: 52.5
B20: P7 1^ misura | C20: 45602 | D20: 1143 ÷1214 | E20: 60 (*) | F20: 60 | G20: -- | H20: -- | I20: -- | J20: 60
B21: P7 2^ misura | C21: 45631 | D21: 1635 ÷1705 | E21: 62,4 (*) | F21: 62.5 | G21: -- | H21: -- | I21: -- | J21: 62.5
C22: (*) valore dell'indice percentile L95 associato alle misure

Sheet 9. Monit. Ind. di Performances
C5: Indici di monitoraggio della prestazione | H5: Unità di misura | I5: Riscontro 2024
C7: Consumo specifico di acqua | G7: Rapporto tra il consumo di acqua ed il tasso di produzione | H7: m3/t | I7: ='2. Sistema idrico'!S5/('1. Materie prime e prodotti'!Q12+'1. Materie prime e prodotti'!Q13+'1. Materie prime e prodotti'!Q14) -> 0.089057036
C8: Consumo specifico di energia | G8: Tabella 14 delle BATc sigla FDM | H8: kWh/t | I8: =('4. Sistema energetico'!I17+'4. Sistema energetico'!J17)/('1. Materie prime e prodotti'!Q12+'1. Materie prime e prodotti'!Q13+'1. Materie prime e prodotti'!Q14) -> 111.74628

Sheet PZ1_Acque sotterranee
E2: Rapporto di prova | G2: 1.29_24 | H2: 365052-241217 | I2: 379073-269723 | J2: 392030-304195
E3: Punto di prelievo | G3: PZ1 | H3: PZ1 | I3: PZ1 | J3: PZ1
E4: Tipologia | G4: Acque di falda | H4: Acque di falda | I4: Acque di falda | J4: Acque di falda
E5: Data Prelievo | G5: 45316 | H5: 45453 | I5: 45547 | J5: 45643
E6: Luogo del prelievo | G6: Stabilimento Grandi Molini Italiani Livorno | H6: Stabilimento Grandi Molini Italiani Livorno | I6: Stabilimento Grandi Molini Italiani Livorno | J6: Stabilimento Grandi Molini Italiani Livorno
B7: Punto di prelievo | C7: Parametro | D7: Frequenza | E7: Metodica | F7: UM | G7: Risultato | H7: Risultato | I7: Risultato | J7: Risultato | K7: Limiti
B8: PZ1 | C8: pH | D8: annuale | E8: APAT CNR IRSA 2060 Man 29 2003 | F8: upH | G8: 7.4 | H8: 7,60 | I8: 7,48 | J8: 7,68 | K8: /
C9: Conducibilità elettrica | D9: annuale | E9: APAT2030-campo | F9: µS/cm | G9: 1831 | H9: 4570 | I9: 3500 | J9: 1698 | K9: /
C10: Alluminio | D10: annuale | E10: EPA 6020B 2014 | F10: µg/l | G10: 9.4 | H10: 70 | I10: 14,1 | J10: <10,0 | K10: 200
C11: Antimonio | D11: annuale | E11: EPA 6020B 2014 | F11: µg/l | G11: <0,5 | H11: <0,50 | I11: <0,50 | J11: 0,72 | K11: 5
C12: Arsenico | D12: annuale | E12: EPA 6020B 2014 | F12: µg/l | G12: 1.88 | H12: 1,12 | I12: 1,68 | J12: 3,3 | K12: 10
C13: Cadmio | D13: annuale | E13: EPA 6020B 2014 | F13: µg/l | G13: <0,25 | H13: <0,3 | I13: <0,3 | J13: <0,3 | K13: 5
C14: Cromo totale | D14: annuale | E14: EPA 6020B 2014 | F14: µg/l | G14: <1 | H14: <1,00 | I14: <1,00 | J14: <1,00 | K14: 50
C15: Cromo (VI) | D15: annuale | E15: EPA 7199 1996 | F15: µg/l | G15: <0,1 | H15: <0,50 | I15: <0,50 | J15: <0,50 | K15: 5
C16: Ferro | D16: annuale | E16: EPA 6010D 2018 | F16: µg/l | G16: 709 | H16: 1050 | I16: 590 | J16: 136 | K16: 200
C17: Mercurio | D17: annuale | E17: EPA 6020B 2014 | F17: µg/l | G17: <0,02 | H17: <0,10 | I17: <0,10 | J17: <0,10 | K17: 1
C18: Nichel | D18: annuale | E18: EPA 6020B 2014 | F18: µg/l | G18: <1 | H18: <1,00 | I18: <1,00 | J18: <1,00 | K18: 20
C19: Piombo | D19: annuale | E19: EPA 6020B 2014 | F19: µg/l | G19: <1 | H19: <0,50 | I19: <0,50 | J19: <0,50 | K19: 10
C20: Rame | D20: annuale | E20: EPA 6020B 2014 | F20: µg/l | G20: <5 | H20: <1,00 | I20: <1,00 | J20: <1,00 | K20: 1000
C21: Selenio | D21: annuale | E21: EPA 6020B 2014 | F21: µg/l | G21: <1 | H21: <1,00 | I21: <1,00 | J21: <1,00 | K21: 10
C22: Manganese | D22: annuale | E22: EPA 6020B 2014 | F22: µg/l | G22: 462 | H22: 418 | I22: 410 | J22: 285 | K22: 50
C23: Zinco | D23: annuale | E23: EPA 6020B 2014 | F23: µg/l | G23: 14 | H23: <10 | I23: 13,4 | J23: <10 | K23: 3000
C24: Boro | D24: annuale | E24: EPA 6020B 2014 | F24: µg/l | G24: 1241 | H24: 1140 | I24: 1080 | J24: 635 | K24: 1000
C25: Cianuri liberi | D25: annuale | E25: UNI EN ISO 14403-2:2013 | F25: µg/l | G25: <5 | H25: <1,00 | I25: <1,00 | J25: <1,00 | K25: 50
C26: Fluoruri | D26: annuale | E26: APAT CNR IRSA 4020 Man 29 2003 | F26: µg/l | G26: 1.3 | H26: 1210 | I26: 1030 | J26: <1000 | K26: 1500
C27: Benzene | D27: annuale | E27: EPA 5030C 2003 + EPA 8260D 2018 | F27: µg/l | G27: <0,05 | H27: <0,05 | I27: 0,029 | J27: <0,05 | K27: 1
C28: Benzo (a) antracene | D28: annuale | E28: EPA 3535A 2007 + EPA 8270E 2018 | F28: µg/l | G28: <0,001 | H28: <0,01 | I28: <0,01 | J28: <0,01 | K28: 0.1
C29: Benzo(a)pirene | D29: annuale | E29: EPA 3535A 2007 + EPA 8270E 2018 | F29: µg/l | G29: <0,001 | H29: <0,001 | I29: <0,001 | J29: <0,001 | K29: 0.01
C30: Benzo (b) fluorantene | D30: annuale | E30: EPA 3535A 2007 + EPA 8270E 2018 | F30: µg/l | G30: <0,001 | H30: <0,00100 | I30: <0,00100 | J30: <0,00100 | K30: 0.1
C31: Benzo (k) fluorantene | D31: annuale | E31: EPA 3535A 2007 + EPA 8270E 2018 | F31: µg/l | G31: <0,001 | H31: <0,00100 | I31: <0,00100 | J31: <0,00100 | K31: 0.05
C32: Benzo (g,h,i) perilene | D32: annuale | E32: EPA 3535A 2007 + EPA 8270E 2018 | F32: µg/l | G32: <0,001 | H32: <0,00100 | I32: <0,00100 | J32: <0,00100 | K32: 0.01
C33: Crisene | D33: annuale | E33: EPA 3535A 2007 + EPA 8270E 2018 | F33: µg/l | G33: <0,001 | H33: <0,1 | I33: <0,1 | J33: <0,1 | K33: 5
C34: Dibenzo (a,h) antracene | D34: annuale | E34: EPA 3535A 2007 + EPA 8270E 2018 | F34: µg/l | G34: <0,001 | H34: <0,001 | I34: <0,001 | J34: <0,001 | K34: 0.01
C35: Indeno (1,2,3 - c,d) pirene | D35: annuale | E35: EPA 3535A 2007 + EPA 8270E 2018 | F35: µg/l | G35: <0,001 | H35: <0,00100 | I35: <0,00100 | J35: <0,00100 | K35: 0.1
C36: Pirene | D36: annuale | E36: EPA 3535A 2007 + EPA 8270E 2018 | F36: µg/l | G36: <0,001 | H36: <0,1 | I36: <0,1 | J36: <0,1 | K36: 50
C37: Sommatoria IPA 31,32,33,36 Tab.2 D.lgs 152/06 (Calcolo) | D37: annuale | E37: EPA 3535A 2007 + EPA 8270E 2018 | F37: µg/l | G37: <0,001 | H37: <0,00200 | I37: <0,050 | J37: <0,00200 | K37: 0.1
C38: Clorometano | D38: annuale | E38: EPA 5030C 2003 + EPA 8260D 2018 | F38: µg/l | G38: <0,05 | H38: <0,0400 | I38: <0,050 | J38: <0,0400 | K38: 1.5
... C40: Cloruro di Vinile | D40: annuale | E40: EPA 5030C 2003 + EPA 8260D 2018 | F40: µg/l | G40: <0,05 | H40: <0,0500 | I40: 0,49 | J40: 0,095 | K40: 0.5
C41: 1,2 - Dicloroetano | D41: annuale | E41: EPA 5030C 2003 + EPA 8260D 2018 | F41: µg/l | G41: 0.193 | H41: 0,193 | I41: 0,075 | J41: 0,115 | K41: 3
C42: 1,1 - Dicloroetilene | D42: annuale | E42: EPA 5030C 2003 + EPA 8260D 2018 | F42: µg/l | G42: <0,005 | H42: <0,00500 | I42: 0,0135 | J42: <0,00500 | K42: 0.05
...

Sheet PZ2_Acque sotterranee
E2: Rapporto di prova | G2: 2.29_24 | H2: 365052-241218 | I2: 379073-269724 | J2: 392030-304196
E3: Punto di prelievo | G3: PZ2 | H3: PZ2 | I3: PZ2 | J3: PZ2
E4: Tipologia | G4: Acque di falda | H4: Acque di falda | I4: Acque di falda | J4: Acque di falda
E5: Data Prelievo | G5: 45316 | H5: 45453 | I5: 45547 | J5: 45643
E6: Luogo del prelievo | G6: Stabilimento Grandi Molini Italiani Livorno | H6: Stabilimento Grandi Molini Italiani Livorno | I6: Stabilimento Grandi Molini Italiani Livorno | J6: Stabilimento Grandi Molini Italiani Livorno
B7: Punto di prelievo | C7: Parametro | D7: Frequenza | E7: Metodica | F7: UM | G7: Risultato | H7: Risultato | I7: Risultato | J7: Risultato | K7: Limiti
B8: PZ2 | C8: pH | D8: annuale | E8: APAT CNR IRSA 2060 Man 29 2003 | F8: upH | G8: 6.8 | H8: 7,21 | I8: 7,09 | J8: 7,08
C9: Conducibilità elettrica | D9: annuale | E9: APAT2030-campo | F9: µS/cm | G9: 1448 | H9: 2730 | I9: 3560 | J9: 2300
C10: Alluminio | D10: annuale | E10: EPA 6020B 2014 | F10: µg/l | G10: 5.5 | H10: <10,0 | I10: <10,0 | J10: <10,0 | K10: 200
C11: Antimonio | D11: annuale | E11: EPA 6020B 2014 | F11: µg/l | G11: <0,5 | H11: <0,50 | I11: <0,50 | J11: <0,50 | K11: 5
C12: Arsenico | D12: annuale | E12: EPA 6020B 2014 | F12: µg/l | G12: 1.82 | H12: 3,2 | I12: 1,56 | J12: 1,74 | K12: 10
C13: Cadmio | D13: annuale | E13: EPA 6020B 2014 | F13: µg/l | G13: <0,25 | H13: <0,3 | I13: <0,3 | J13: <0,3 | K13: 5
C14: Cromo totale | D14: annuale | E14: EPA 6020B 2014 | F14: µg/l | G14: <1 | H14: <1,00 | I14: <1,00 | J14: <1,00 | K14: 50
C15: Cromo (VI) | D15: annuale | E15: EPA 7199 1996 | F15: µg/l | G15: <0,1 | H15: <0,50 | I15: <0,50 | J15: <5,00 | K15: 5
C16: Ferro | D16: annuale | E16: EPA 6010D 2018 | F16: µg/l | G16: 1161 | H16: 89 | I16: 232 | J16: 530 | K16: 200
C17: Mercurio | D17: annuale | E17: EPA 6020B 2014 | F17: µg/l | G17: <0,02 | H17: <0,10 | I17: <0,10 | J17: <0,10 | K17: 1
C18: Nichel | D18: annuale | E18: EPA 6020B 2014 | F18: µg/l | G18: <1 | H18: <1,00 | I18: 1,02 | J18: <1,00 | K18: 20
C19: Piombo | D19: annuale | E19: EPA 6020B 2014 | F19: µg/l | G19: <1 | H19: <0,50 | I19: <0,50 | J19: <0,50 | K19: 10
C20: Rame | D20: annuale | E20: EPA 6020B 2014 | F20: µg/l | G20: <5 | H20: <1,00 | I20: <1,00 | J20: <1,00 | K20: 1000
C21: Selenio | D21: annuale | E21: EPA 6020B 2014 | F21: µg/l | G21: <1 | H21: <1,00 | I21: <1,00 | J21: 1,05 | K21: 10
C22: Manganese | D22: annuale | E22: EPA 6020B 2014 | F22: µg/l | G22: 1528 | H22: 173 | I22: 960 | J22: 1090 | K22: 50
C23: Zinco | D23: annuale | E23: EPA 6020B 2014 | F23: µg/l | G23: 13 | H23: <10 | I23: <10 | J23: <10 | K23: 3000
C24: Boro | D24: annuale | E24: EPA 6020B 2014 | F24: µg/l | G24: 1588 | H24: 1440 | I24: 1620 | J24: 1460 | K24: 1000
C25: Cianuri liberi | D25: annuale | E25: UNI EN ISO 14403-2:2013 | F25: µg/l | G25: <5 | H25: <1,00 | I25: <1,00 | J25: <1,00 | K25: 50
C26: Fluoruri | D26: annuale | E26: APAT CNR IRSA 4020 Man 29 2003 | F26: µg/l | G26: 0.395 | H26: 410 | I26: 300 | J26: 270 | K26: 1500
C27: Benzene | D27: annuale | E27: EPA 5030C 2003 + EPA 8260D 2018 | F27: µg/l | G27: <0,05 | H27: <0,05 | I27: <0,010 | J27: <0,05 | K27: 1
C28: Benzo (a) antracene | D28: annuale | E28: EPA 3535A 2007 + EPA 8270E 2018 | F28: µg/l | G28: <0,001 | H28: <0,01 | I28: <0,01 | J28: <0,01 | K28: 0.1
C29: Benzo(a)pirene | D29: annuale | E29: EPA 3535A 2007 + EPA 8270E 2018 | F29: µg/l | G29: <0,001 | H29: <0,001 | I29: <0,001 | J29: <0,001 | K29: 0.01
C30: Benzo (b) fluorantene | D30: annuale | E30: EPA 3535A 2007 + EPA 8270E 2018 | F30: µg/l | G30: <0,001 | H30: <0,00100 | I30: <0,00100 | J30: <0,00100 | K30: 0.1
C31: Benzo (k) fluorantene | D31: annuale | E31: EPA 3535A 2007 + EPA 8270E 2018 | F31: µg/l | G31: <0,001 | H31: <0,00100 | I31: <0,00100 | J31: <0,00100 | K31: 0.05
C32: Benzo (g,h,i) perilene | D32: annuale | E32: EPA 3535A 2007 + EPA 8270E 2018 | F32: µg/l | G32: <0,001 | H32: <0,00100 | I32: <0,00100 | J32: <0,00100 | K32: 0.01
C33: Crisene | D33: annuale | E33: EPA 3535A 2007 + EPA 8270E 2018 | F33: µg/l | G33: <0,001 | H33: <0,1 | I33: <0,1 | J33: <0,1 | K33: 5
C34: Dibenzo (a,h) antracene | D34: annuale | E34: EPA 3535A 2007 + EPA 8270E 2018 | F34: µg/l | G34: <0,001 | H34: <0,001 | I34: <0,001 | J34: <0,001 | K34: 0.01
C35: Indeno (1,2,3 - c,d) pirene | D35: annuale | E35: EPA 3535A 2007 + EPA 8270E 2018 | F35: µg/l | G35: <0,001 | H35: <0,00100 | I35: <0,00100 | J35: <0,00100 | K35: 0.1
C36: Pirene | D36: annuale | E36: EPA 3535A 2007 + EPA 8270E 2018 | F36: µg/l | G36: <0,001 | H36: <0,1 | I36: <0,1 | J36: <0,1 | K36: 50
C37: Sommatoria IPA 31,32,33,36 Tab.2 D.lgs 152/06 (Calcolo) | D37: annuale | E37: EPA 3535A 2007 + EPA 8270E 2018 | F37: µg/l | G37: <0,001 | H37: <0,00200 | I37: <0,050 | J37: <0,00200 | K37: 0.1
C38: Clorometano | D38: annuale | E38: EPA 5030C 2003 + EPA 8260D 2018 | F38: µg/l | G38: <0,05 | H38: <0,0400 | I38: <0,050 | J38: <0,0400 | K38: 1.5
... C63: Idrocarburi totali (espressi come n-esano) Calcolo | D63: annuale | E63: EPA 5021A 2014 + EPA 8015 2007 + ISO 9377-2:2002 | F63: µg/l | G63: <35 | H63: <33,0 | I63: <33,0 | J63: <33,0 | K63: 350
C64: Idrocarburi C6÷C10 come n-esano | D64: / | E64: EPA 5021A 2014, EPA 8015C 2007 | F64: µg/l | G64: <35 | H64: <10,0 | I64: <10,0 | J64: <10,0 | K64: /
C65: Idrocarburi estraibili C10-C40 espressi come n-esano | D65: / | E65: UNI EN ISO 9377-2:2002 | F65: µg/l | G65: <35 | H65: <33,0 | I65: <33,0 | J65: <33,0 | K65: /

Sheet PZ3_Acque sotterranee
E2: Rapporto di prova | G2: 3.29_24 | H2: 365052-241219 | I2: 379073-269725 | J2: 392030-304197
E3: Punto di prelievo | G3: PZ3 | H3: PZ3 | I3: PZ3 | J3: PZ3
E4: Tipologia | G4: Acque di falda | H4: Acque di falda | I4: Acque di falda | J4: Acque di falda
E5: Data Prelievo | G5: 45316 | H5: 45453 | I5: 45547 | J5: 45643
E6: Luogo del prelievo | G6: Stabilimento Grandi Molini Italiani Livorno | H6: Stabilimento Grandi Molini Italiani Livorno | I6: Stabilimento Grandi Molini Italiani Livorno | J6: Stabilimento Grandi Molini Italiani Livorno
B7: Punto di prelievo | C7: Parametro | D7: Frequenza | E7: Metodica | F7: UM | G7: Risultato | H7: Risultato | I7: Risultato | J7: Risultato | K7: Limiti
B8: PZ3 | C8: pH | D8: annuale | E8: APAT CNR IRSA 2060 Man 29 2003 | F8: upH | G8: 7.4 | H8: 7,56 | I8: 7,44 | J8: 7,65
C9: Conducibilità elettrica | D9: annuale | E9: APAT2030-campo | F9: µS/cm | G9: 4439 | H9: 6830 | I9: 21100 | J9: 10630
C10: Alluminio | D10: annuale | E10: EPA 6020B 2014 | F10: µg/l | G10: 7.4 | H10: <10,0 | I10: 21,0 | J10: 24,0 | K10: 200
C11: Antimonio | D11: annuale | E11: EPA 6020B 2014 | F11: µg/l | G11: <0,5 | H11: <0,50 | I11: <0,50 | J11: <0,50 | K11: 5
C12: Arsenico | D12: annuale | E12: EPA 6020B 2014 | F12: µg/l | G12: 5.28 | H12: 3,6 | I12: 2,77 | J12: 13,1 | K12: 10
C13: Cadmio | D13: annuale | E13: EPA 6020B 2014 | F13: µg/l | G13: <0,25 | H13: <0,3 | I13: <0,3 | J13: <0,3 | K13: 5
C14: Cromo totale | D14: annuale | E14: EPA 6020B 2014 | F14: µg/l | G14: <1 | H14: <1,00 | I14: 1,38 | J14: <1,00 | K14: 50
C15: Cromo (VI) | D15: annuale | E15: EPA 7199 1996 | F15: µg/l | G15: <0,1 | H15: <0,50 | I15: <5,00 | J15: <5,00 | K15: 5
C16: Ferro | D16: annuale | E16: EPA 6010D 2018 | F16: µg/l | G16: 547 | H16: 520 | I16: 831 | J16: 550 | K16: 200
C17: Mercurio | D17: annuale | E17: EPA 6020B 2014 | F17: µg/l | G17: <0,02 | H17: <0,10 | I17: 0,83 | J17: <0,10 | K17: 1
C18: Nichel | D18: annuale | E18: EPA 6020B 2014 | F18: µg/l | G18: <1 | H18: <1,00 | I18: <1,00 | J18: <1,00 | K18: 20
C19: Piombo | D19: annuale | E19: EPA 6020B 2014 | F19: µg/l | G19: <1 | H19: <0,50 | I19: <0,50 | J19: <0,50 | K19: 10
C20: Rame | D20: annuale | E20: EPA 6020B 2014 | F20: µg/l | G20: <5 | H20: <1,00 | I20: <1,00 | J20: <1,00 | K20: 1000
C21: Selenio | D21: annuale | E21: EPA 6020B 2014 | F21: µg/l | G21: <1 | H21: <1,00 | I21: 1,45 | J21: <1,00 | K21: 10
C22: Manganese | D22: annuale | E22: EPA 6020B 2014 | F22: µg/l | G22: 339 | H22: 285 | I22: 307 | J22: 194 | K22: 50
C23: Zinco | D23: annuale | E23: EPA 6020B 2014 | F23: µg/l | G23: 50 | H23: <10 | I23: 18,6 | J23: <10 | K23: 3000
C24: Boro | D24: annuale | E24: EPA 6020B 2014 | F24: µg/l | G24: 4222 | H24: 4350 | I24: 4200 | J24: 4310 | K24: 1000
C25: Cianuri liberi | D25: annuale | E25: UNI EN ISO 14403-2:2013 | F25: µg/l | G25: <5 | H25: <1,00 | I25: <1,00 | J25: <1,00 | K25: 50
C26: Fluoruri | D26: annuale | E26: APAT CNR IRSA 4020 Man 29 2003 | F26: µg/l | G26: 1.46 | H26: 1330 | I26: 1080 | J26: 1470 | K26: 1500
C27: Benzene | D27: annuale | E27: EPA 5030C 2003 + EPA 8260D 2018 | F27: µg/l | G27: <0,05 | H27: <0,05 | I27: <0,010 | J27: <0,05 | K27: 1
C28: Benzo (a) antracene | D28: annuale | E28: EPA 3535A 2007 + EPA 8270E 2018 | F28: µg/l | G28: <0,001 | H28: <0,01 | I28: <0,01 | J28: <0,01 | K28: 0.1
C29: Benzo(a)pirene | D29: annuale | E29: EPA 3535A 2007 + EPA 8270E 2018 | F29: µg/l | G29: <0,001 | H29: <0,001 | I29: <0,001 | J29: <0,001 | K29: 0.01
C30: Benzo (b) fluorantene | D30: annuale | E30: EPA 3535A 2007 + EPA 8270E 2018 | F30: µg/l | G30: <0,001 | H30: <0,00100 | I30: <0,00100 | J30: <0,00100 | K30: 0.1
C31: Benzo (k) fluorantene | D31: annuale | E31: EPA 3535A 2007 + EPA 8270E 2018 | F31: µg/l | G31: <0,001 | H31: <0,00100 | I31: <0,00100 | J31: <0,00100 | K31: 0.05
C32: Benzo (g,h,i) perilene | D32: annuale | E32: EPA 3535A 2007 + EPA 8270E 2018 | F32: µg/l | G32: <0,001 | H32: <0,00100 | I32: <0,00100 | J32: <0,00100 | K32: 0.01
C33: Crisene | D33: annuale | E33: EPA 3535A 2007 + EPA 8270E 2018 | F33: µg/l | G33: <0,001 | H33: <0,1 | I33: <0,1 | J33: <0,1 | K33: 5
C34: Dibenzo (a,h) antracene | D34: annuale | E34: EPA 3535A 2007 + EPA 8270E 2018 | F34: µg/l | G34: <0,001 | H34: <0,001 | I34: <0,001 | J34: <0,001 | K34: 0.01
C35: Indeno (1,2,3 - c,d) pirene | D35: annuale | E35: EPA 3535A 2007 + EPA 8270E 2018 | F35: µg/l | G35: <0,001 | H35: <0,00100 | I35: <0,00100 | J35: <0,00100 | K35: 0.1
C36: Pirene | D36: annuale | E36: EPA 3535A 2007 + EPA 8270E 2018 | F36: µg/l | G36: <0,001 | H36: <0,1 | I36: <0,1 | J36: <0,1 | K36: 50
C37: Sommatoria IPA 31,32,33,36 Tab.2 D.lgs 152/06 (Calcolo) | D37: annuale | E37: EPA 3535A 2007 + EPA 8270E 2018 | F37: µg/l | G37: <0,001 | H37: <0,00200 | I37: <0,050 | J37: <0,00200 | K37: 0.1
C38: Clorometano | D38: annuale | E38: EPA 5030C 2003 + EPA 8260D 2018 | F38: µg/l | G38: <0,05 | H38: <0,0400 | I38: <0,050 | J38: <0,0400 | K38: 1.5
... C63: Idrocarburi totali (espressi come n-esano) Calcolo | D63: annuale | E63: EPA 5021A 2014 + EPA 8015 2007 + ISO 9377-2:2002 | F63: µg/l | G63: <35 | H63: <33,0 | I63: <33,0 | J63: <33,0 | K63: 350
C64: Idrocarburi C6÷C10 come n-esano | D64: / | E64: EPA 5021A 2014, EPA 8015C 2007 | F64: µg/l | G64: <35 | H64: <10,0 | I64: <10,0 | J64: <10,0 | K64: /
C65: Idrocarburi estraibili C10-C40 espressi come n-esano | D65: / | E65: UNI EN ISO 9377-2:2002 | F65: µg/l | G65: <35 | H65: <33,0 | I65: <33,0 | J65: <33,0 | K65: /

Sheet PZ4_Acque sotterranee
E2: Rapporto di prova | G2: 4.29_24 | H2: 365052-241220 | I2: 379073-269726 | J2: 392030-304198
E3: Punto di prelievo | G3: PZ4 | H3: PZ4 | I3: PZ4 | J3: PZ4
E4: Tipologia | G4: Acque di falda | H4: Acque di falda | I4: Acque di falda | J4: Acque di falda
E5: Data Prelievo | G5: 45316 | H5: 45453 | I5: 45547 | J5: 45643
E6: Luogo del prelievo | G6: Stabilimento Grandi Molini Italiani Livorno | H6: Stabilimento Grandi Molini Italiani Livorno | I6: Stabilimento Grandi Molini Italiani Livorno | J6: Stabilimento Grandi Molini Italiani Livorno
B7: Punto di prelievo | C7: Parametro | D7: Frequenza | E7: Metodica | F7: UM | G7: Risultato | H7: Risultato | I7: Risultato | J7: Risultato | K7: Limiti
B8: PZ4 | C8: pH | D8: annuale | E8: APAT CNR IRSA 2060 Man 29 2003 | F8: upH | G8: 7 | H8: 7,17 | I8: 7,11 | J8: 7,25
C9: Conducibilità elettrica | D9: annuale | E9: APAT2030-campo | F9: µS/cm | G9: 640 | H9: 983 | I9: 890 | J9: 1084
C10: Alluminio | D10: annuale | E10: EPA 6020B 2014 | F10: µg/l | G10: 11 | H10: <10,0 | I10: 12,4 | J10: 41 | K10: 200
C11: Antimonio | D11: annuale | E11: EPA 6020B 2014 | F11: µg/l | G11: 0.612 | H11: <0,50 | I11: <0,50 | J11: <0,50 | K11: 5
C12: Arsenico | D12: annuale | E12: EPA 6020B 2014 | F12: µg/l | G12: 10 | H12: 12,1 | I12: 24,2 | J12: 20,1 | K12: 10
C13: Cadmio | D13: annuale | E13: EPA 6020B 2014 | F13: µg/l | G13: <0,25 | H13: <0,3 | I13: <0,3 | J13: <0,3 | K13: 5
C14: Cromo totale | D14: annuale | E14: EPA 6020B 2014 | F14: µg/l | G14: <1 | H14: <1,00 | I14: <1,00 | J14: <1,00 | K14: 50
C15: Cromo (VI) | D15: annuale | E15: EPA 7199 1996 | F15: µg/l | G15: <0,1 | H15: <0,50 | I15: <0,50 | J15: <0,50 | K15: 5
C16: Ferro | D16: annuale | E16: EPA 6010D 2018 | F16: µg/l | G16: 3046 | H16: 3150 | I16: 3070 | J16: 3210 | K16: 200
C17: Mercurio | D17: annuale | E17: EPA 6020B 2014 | F17: µg/l | G17: 0.0485 | H17: <0,10 | I17: <0,10 | J17: <0,10 | K17: 1
C18: Nichel | D18: annuale | E18: EPA 6020B 2014 | F18: µg/l | G18: <1 | H18: <1,00 | I18: <1,00 | J18: <1,00 | K18: 20
C19: Piombo | D19: annuale | E19: EPA 6020B 2014 | F19: µg/l | G19: <1 | H19: <0,50 | I19: <0,50 | J19: <0,50 | K19: 10
C20: Rame | D20: annuale | E20: EPA 6020B 2014 | F20: µg/l | G20: <5 | H20: <1,00 | I20: <1,00 | J20: <1,00 | K20: 1000
C21: Selenio | D21: annuale | E21: EPA 6020B 2014 | F21: µg/l | G21: <1 | H21: <1,00 | I21: <1,00 | J21: <1,00 | K21: 10
C22: Manganese | D22: annuale | E22: EPA 6020B 2014 | F22: µg/l | G22: 1080 | H22: 1020 | I22: 920 | J22: 1030 | K22: 50
C23: Zinco | D23: annuale | E23: EPA 6020B 2014 | F23: µg/l | G23: 6.7 | H23: 11,7 | I23: <10 | J23: <10 | K23: 3000
C24: Boro | D24: annuale | E24: EPA 6020B 2014 | F24: µg/l | G24: 535 | H24: 598 | I24: 740 | J24: 720 | K24: 1000
C25: Cianuri liberi | D25: annuale | E25: UNI EN ISO 14403-2:2013 | F25: µg/l | G25: <5 | H25: <1,00 | I25: <1,00 | J25: <1,00 | K25: 50
C26: Fluoruri | D26: annuale | E26: APAT CNR IRSA 4020 Man 29 2003 | F26: µg/l | G26: 0.92 | H26: 810 | I26: 860 | J26: 880 | K26: 1500
C27: Benzene | D27: annuale | E27: EPA 5030C 2003 + EPA 8260D 2018 | F27: µg/l | G27: <0,05 | H27: <0,05 | I27: <0,010 | J27: <0,05 | K27: 1
C28: Benzo (a) antracene | D28: annuale | E28: EPA 3535A 2007 + EPA 8270E 2018 | F28: µg/l | G28: <0,001 | H28: <0,01 | I28: <0,01 | J28: <0,01 | K28: 0.1
C29: Benzo(a)pirene | D29: annuale | E29: EPA 3535A 2007 + EPA 8270E 2018 | F29: µg/l | G29: <0,001 | H29: <0,001 | I29: <0,001 | J29: <0,001 | K29: 0.01
C30: Benzo (b) fluorantene | D30: annuale | E30: EPA 3535A 2007 + EPA 8270E 2018 | F30: µg/l | G30: <0,001 | H30: <0,00100 | I30: <0,00100 | J30: <0,00100 | K30: 0.1
C31: Benzo (k) fluorantene | D31: annuale | E31: EPA 3535A 2007 + EPA 8270E 2018 | F31: µg/l | G31: <0,001 | H31: <0,00100 | I31: <0,00100 | J31: <0,00100 | K31: 0.05
C32: Benzo (g,h,i) perilene | D32: annuale | E32: EPA 3535A 2007 + EPA 8270E 2018 | F32: µg/l | G32: <0,001 | H32: <0,00100 | I32: <0,00100 | J32: <0,00100 | K32: 0.01
C33: Crisene | D33: annuale | E33: EPA 3535A 2007 + EPA 8270E 2018 | F33: µg/l | G33: <0,001 | H33: <0,1 | I33: <0,1 | J33: <0,1 | K33: 5
C34: Dibenzo (a,h) antracene | D34: annuale | E34: EPA 3535A 2007 + EPA 8270E 2018 | F34: µg/l | G34: <0,001 | H34: <0,001 | I34: <0,001 | J34: <0,001 | K34: 0.01
C35: Indeno (1,2,3 - c,d) pirene | D35: annuale | E35: EPA 3535A 2007 + EPA 8270E 2018 | F35: µg/l | G35: <0,001 | H35: <0,00100 | I35: <0,00100 | J35: <0,00100 | K35: 0.1
C36: Pirene | D36: annuale | E36: EPA 3535A 2007 + EPA 8270E 2018 | F36: µg/l | G36: <0,001 | H36: <0,1 | I36: <0,1 | J36: <0,1 | K36: 50
C37: Sommatoria IPA 31,32,33,36 Tab.2 D.lgs 152/06 (Calcolo) | D37: annuale | E37: EPA 3535A 2007 + EPA 8270E 2018 | F37: µg/l | G37: <0,001 | H37: <0,00200 | I37: <0,050 | J37: <0,00200 | K37: 0.1
C38: Clorometano | D38: annuale | E38: EPA 5030C 2003 + EPA 8260D 2018 | F38: µg/l | G38: <0,05 | H38: <0,0400 | I38: <0,050 | J38: <0,0400 | K38: 1.5
... C63: Idrocarburi totali (espressi come n-esano) Calcolo | D63: annuale | E63: EPA 5021A 2014 + EPA 8015 2007 + ISO 9377-2:2002 | F63: µg/l | G63: <35 | H63: <33,0 | I63: <33,0 | J63: <33,0 | K63: 350
C64: Idrocarburi C6÷C10 come n-esano | D64: / | E64: EPA 5021A 2014, EPA 8015C 2007 | F64: µg/l | G64: <35 | H64: <10,0 | I64: <10,0 | J64: <10,0 | K64: /
C65: Idrocarburi estraibili C10-C40 espressi come n-esano | D65: / | E65: UNI EN ISO 9377-2:2002 | F65: µg/l | G65: <35 | H65: <33,0 | I65: <33,0 | J65: <33,0 | K65: /

Sheet Foglio2

Sheet Foglio1
