Workbook

Sheet ANAGRAFICA AZIENDA
A2: Autorizzazione Integrata Ambientale - Direttiva IPPC
A3: REPORT ANNUALE PER L'INVIO DEI DATI DI AUTOCONTROLLO
A4: Modello generale per tutte le attività dell'allegato I del D.Lgs.59/2005
A5: (escluse le attività IPPC 5 e 6.6 Allegato I e attività Allegato V del D.Lgs.59/2005)
C7: ANAGRAFICA AZIENDA
C10: ANNO DI RIFERIMENTO | F10: dal | G10: 45292 | I10: al | J10: 45657
C13: Ragione sociale: | E13: Promolog Srl
C15: Categoria IPPC | E15: 6.4b
C17: PIVA | E17: 01132290295
C19: Indirizzo impianto: | E19: via | F19: Zurlare
E21: n° | F21: 21 | H21: CAP | I21: 37041
E23: città | F23: Coriano Veronese (Comune di Albaredo d'Adige)
C27: Referente IPPC: | E27: Mauro Pasetto
F29: tel: | G29: 045 6629125 | I29: fax: | J29: 045 7025031
F31: e-mail: | G31: mpasetto@grandimolini.it
C35: Compilatore report annuale IPPC:
F36: Mauro Pasetto
F38: tel: | G38: 045 6629125
F40: e-mail: | G40: mpasetto@grandimolini.it
C43: Numero giorni lavorati in un anno | G43: 300

Sheet MATERIE PRIME
A2: 1 - COMPONENTI AMBIENTALI
A4: 1.1. Materie prime e prodotti in ingresso e in uscita
F5: In Ingresso
A7: Tabella 1.1.1. Materie prime
A9: Denominazione | O9: U.M.
B10: GENNAIO | C10: FEBBRAIO | D10: MARZO | E10: APRILE | F10: MAGGIO | G10: GIUGNO | H10: LUGLIO | I10: AGOSTO | J10: SETTEMBRE | K10: OTTOBRE | L10: NOVEMBRE | M10: DICEMBRE | N10: TOTALE ANNO
A11: Grano | B11: 5172.53 | C11: 4700.297 | D11: 4132.25 | E11: 4903.73 | F11: 2903.41 | G11: 2543.94 | H11: 4863.8 | I11: 4008.37 | J11: 5033.68 | K11: 5825.03 | L11: 5677 | M11: 4843.13 | N11: =SUM(B11:M11) -> 54607.167 | O11: t
A12: Farina sfusa (da altri stabilimenti del gruppo) | B12: 342.54 | C12: 371.04 | D12: 417.08 | E12: 415.44 | F12: 626.46 | G12: 515.84 | H12: 383.8 | I12: 352.62 | J12: 762.8 | K12: 1042.98 | L12: 844.14 | M12: 1016.34 | N12: =SUM(B12:M12) -> 7091.08 | O12: t
A13: Farina già confezionata (da altri stabilimenti del gruppo) | B13: 129.4 | C13: 123.5 | D13: 125.08 | E13: 125.48 | F13: 154.8 | G13: 94.74 | H13: 220.2 | I13: 56.1 | J13: 141.12 | K13: 159.8 | L13: 149.4 | M13: 178.87 | N13: =SUM(B13:M13) -> 1658.49 | O13: t
N14: =SUM(B14:M14) -> 0
N15: =SUM(B15:M15) -> 0
N16: =SUM(B16:M16) -> 0
N17: =SUM(B17:M17) -> 0
N18: =SUM(B18:M18) -> 0
N19: =SUM(B19:M19) -> 0
N20: =SUM(B20:M20) -> 0
N21: =SUM(B21:M21) -> 0
N22: =SUM(B22:M22) -> 0
N23: =SUM(B23:M23) -> 0
N24: =SUM(B24:M24) -> 0
A27: Tabella 1.1.2. - Altre materie e sostanze in ingresso
A30: Denominazione | O30: U.M.
B31: GENNAIO | C31: FEBBRAIO | D31: MARZO | E31: APRILE | F31: MAGGIO | G31: GIUGNO | H31: LUG.IO | I31: AGOSTO | J31: SETTEMBRE | K31: OTTOBRE | L31: NOVEMBRE | M31: DICEMBRE | N31: TOTALE ANNO
A32: Carta per confezionamento | B32: =34.72+16.66 -> 51.38 | C32: 18.31 | D32: 5.76 | E32: =4.27+8.92 -> 13.19 | F32: =3.91+3.67+2.41+5.81+4.62+3.42 -> 23.84 | G32: =2.51+6.38+12.16+8.96 -> 30.01 | H32: =5.745+9.42+4.71+2.11 -> 21.985 | I32: =5.04+4.26+5.72 -> 15.02 | J32: =6.89+0.36+18.49+5.92+8.54+13.7 -> 53.9 | K32: =7.62+12.89+0.96+15.77+13.75+9.99 -> 60.98 | L32: =6.87+16.28+17.19 -> 40.34 | M32: =14.52+4.79+5.43+13.86 -> 38.6 | N32: =SUM(B32:M32) -> 373.315 | O32: t
A33: Termosaldato per confezionamento | C33: 0.46 | L33: 0.34 | N33: =SUM(B33:M33) -> 0.8 | O33: t
A34: Film estensibile | B34: 9.61 | E34: =4.81+4.82 -> 9.63 | H34: 0.74 | J34: 2.65 | K34: 1.48 | L34: 0.56 | N34: =SUM(B34:M34) -> 24.67 | O34: t
A35: Film termoretraibile | B35: =10.02+2.03 -> 12.05 | E35: 8.07 | F35: 8.48 | G35: 2.07 | I35: 4.16 | J35: =6.77+2.01 -> 8.78 | K35: 5.1 | L35: 0.13 | M35: =3.39+2.03 -> 5.42 | N35: =SUM(B35:M35) -> 54.26 | O35: t
A36: Polistirolo | B36: 0.41 | C36: 0.24 | E36: =0.5+0.24 -> 0.74 | N36: =SUM(B36:M36) -> 1.39 | O36: t
A37: Cartone | B37: 19.1 | D37: 5.27 | E37: =8.44+5.37 -> 13.81 | F37: 7.8 | G37: 5.52 | H37: 6.97 | I37: 2.22 | J37: =4.89+4.38 -> 9.27 | K37: 24.63 | L37: 19.93 | M37: 8.39 | N37: =SUM(B37:M37) -> 122.91 | O37: t
A38: Pallet | B38: 2.26 | C38: 0.82 | D38: 0.41 | E38: 0.36 | G38: 0.09 | H38: =0.6+0.81 -> 1.41 | I38: 0.11 | J38: 1.19 | K38: 0.11 | L38: 0.33 | M38: 0.38 | N38: =SUM(B38:M38) -> 7.47 | O38: t
A39: Colla solida | B39: 0.98 | G39: 0.6 | L39: 1.8 | M39: 1.2 | N39: =SUM(B39:M39) -> 4.58 | O39: t
A40: Colla liquida | B40: 2.16 | D40: 0.54 | F40: 2.03 | H40: 3.19 | M40: =2.17+0.54 -> 2.71 | N40: =SUM(B40:M40) -> 10.63 | O40: t
A41: Sostanze chimiche pericolose | E41: 0.06 | H41: 0.06 | N41: =SUM(B41:M41) -> 0.12 | O41: t
A42: Prodotti usati per la sanificazione degli impianti (disinfestanti) | N42: =SUM(B42:M42) -> 0 | O42: t
N43: =SUM(B43:M43) -> 0
N44: =SUM(B44:M44) -> 0
A47: Tabella 1.1.3. Sottoprodotti (art. 183 D.Lgs. 152/2006 s.m.i) e Materie Prime Secondarie
A50: Denominazione | O50: U.M.
B51: GENNAIO | C51: FEBBRAIO | D51: MARZO | E51: APRILE | F51: MAGGIO | G51: GIUGNO | H51: LUG.IO | I51: AGOSTO | J51: SETTEMBRE | K51: OTTOBRE | L51: NOVEMBRE | M51: DICEMBRE | N51: TOTLAE ANNO
A52: --- | N52: =SUM(B52:M52) -> 0
...

Sheet ACQUA ED ENERGIA
A1: 1 - COMPONENTI AMBIENTALI
A3: 1.2. Risorse idriche
A5: Tabella 1.2.1. Risorse idriche
S6: EQUIVALENTE ENERGETICO DI ALCUNI PRODOTTI COMBUSTIBILI ED ENERGIA (Valori indicativi espressi in TEP primari per unità fisica di prodotto) (da TABELLA A - Circolare M.I.C.A. del 2 marzo 1992 n.219/F e Delibera EEN 3/08)
A7: Tipologia di approvvigionamento | B7: GENNAIO | C7: FEBBRAIO | D7: MARZO | E7: APRILE | F7: MAGGIO | G7: GIUGNO | H7: LUGLIO | I7: AGOSTO | J7: SETTEMBRE | K7: OTTOBRE | L7: NOVEMBRE | M7: DICEMBRE | N7: TOTALE ANNUO | O7: U.M.
O8: UM | R8: Gasolio 1 t | S8: = 1,08 TEP
A9: Acquedotto Fase 2 -molino (bagnatura grano) | B9: 298 | C9: 235 | D9: 260 | E9: 277 | F9: 204 | G9: 156 | H9: 213 | I9: 171 | J9: 286 | K9: 342 | L9: 401 | M9: 298 | N9: =SUM(B9:M9) -> 3141 | O9: m3 | R9: Olio combustibile 1 t | S9: = 0,98 TEP
A10: Acquedotto Fase 8 -servizi | B10: 48 | C10: 128 | D10: 169 | E10: 73 | F10: 43 | G10: 76 | H10: 59 | I10: 47 | J10: 122 | K10: 143 | L10: 101 | M10: 82 | N10: =SUM(B10:M10) -> 1091 | O10: m3 | R10: Gas di petrolio liquefatti (GPL) 1 t | S10: = 1,10 TEP
N11: =SUM(B11:M11) -> 0 | R11: Carbon fossile 1 t | S11: = 0,74 TEP
N12: =SUM(B12:M12) -> 0 | R12: Carbone di legna 1 t | S12: = 0,75 TEP
N13: =SUM(B13:M13) -> 0 | R13: Antracite e prodotti antracinosi 1 t | S13: = 0,70 TEP
N14: =SUM(B14:M14) -> 0 | R14: Legna da ardere 1 t | S14: = 0,45 TEP
N15: =SUM(B15:M15) -> 0 | R15: Lignite 1 t | S15: = 0,25 TEP
N16: =SUM(B16:M16) -> 0 | R16: Gas naturale 1000 Nm3 | S16: = 0,82 TEP
N17: =SUM(B17:M17) -> 0 | R17: 1 kWh | S17: = 0,187 X 10-3
N18: =SUM(B18:M18) -> 0
N19: =SUM(B19:M19) -> 0
N20: =SUM(B20:M20) -> 0
O21: =SUM(N9:N20) -> 4232 | P21: TOTALE
A22: 1.3. Energia
A24: Tabella 1.3.1. Risorse energetiche
A26: Si calcolino i TEP utilizzando i valori riportati nella tabella di destra.
A27: Descrizione | Z27: TOTALE | AA27: data
B28: GENNAIO | D28: FEBBRAIO | F28: MARZO | H28: APRILE | J28: MAGGIO | L28: GIUGNO | N28: LUGLIO | P28: AGOSTO | R28: SETTEMBRE | T28: OTTOBRE | V28: NOVEMBRE | X28: DICEMBRE | Z28: ANNO | AB28: U.M. utilizzata
C29: TEP | E29: TEP | G29: TEP | I29: TEP | K29: TEP | M29: TEP | O29: TEP | Q29: TEP | S29: TEP | T29: data___ | U29: TEP | W29: TEP | Y29: TEP | AA29: TEP
A30: Energia importata da rete esterna | B30: 492531 | C30: =B30*(0.187/1000) -> 92.103297 | D30: 474822 | E30: =D30*(0.187/1000) -> 88.791714 | F30: 515442 | G30: =F30*(0.187/1000) -> 96.387654 | H30: 442517 | I30: =H30*(0.187/1000) -> 82.750679 | J30: 357141 | K30: =J30*(0.187/1000) -> 66.785367 | L30: 295305 | M30: =L30*(0.187/1000) -> 55.222035 | N30: 365195 | O30: =N30*(0.187/1000) -> 68.291465 | P30: 355005 | Q30: =P30*(0.187/1000) -> 66.385935 | R30: 469077 | S30: =R30*(0.187/1000) -> 87.717399 | T30: 551812 | U30: =T30*(0.187/1000) -> 103.18884 | V30: 641132 | W30: =V30*(0.187/1000) -> 119.89168 | X30: 558725 | Y30: =X30*(0.187/1000) -> 104.48157 | Z30: =SUM(X30,V30,T30,R30,P30,N30,L30,J30,H30,F30,D30,B30) -> 5518704 | AA30: =SUM(C30,E30,G30,I30,K30,M30,O30,Q30,S30,U30,W30,Y30) -> 1031.9976 | AB30: Kwh
A31: Produzione energia rinnovabile (pannelli fotovoltaici) | B31: 19626 | C31: =-B31*(0.187/1000) -> -3.670062 | D31: 23344 | E31: =-D31*(0.187/1000) -> -4.365328 | F31: 35862 | G31: =-F31*(0.187/1000) -> -6.706194 | H31: 44109 | I31: =-H31*(0.187/1000) -> -8.248383 | J31: 40114 | K31: =-J31*(0.187/1000) -> -7.501318 | L31: 46041 | M31: =-L31*(0.187/1000) -> -8.609667 | N31: 58455 | O31: =-N31*(0.187/1000) -> -10.931085 | P31: 49464 | Q31: =-P31*(0.187/1000) -> -9.249768 | R31: 31777 | S31: =-R31*(0.187/1000) -> -5.942299 | T31: 20175 | U31: =-T31*(0.187/1000) -> -3.772725 | V31: 24215 | W31: =-V31*(0.187/1000) -> -4.528205 | X31: 17844 | Y31: =-X31*(0.187/1000) -> -3.336828 | Z31: =SUM(X31,V31,T31,R31,P31,N31,L31,J31,H31,F31,D31,B31) -> 411026 | AA31: =SUM(C31,E31,G31,I31,K31,M31,O31,Q31,S31,U31,W31,Y31) -> -76.861862 | AB31: Kwh
Z32: =SUM(X32,V32,T32,R32,P32,N32,L32,J32,H32,F32,D32,B32) -> 0 | AA32: =SUM(C32,E32,G32,I32,K32,M32,O32,Q32,S32,U32,W32,Y32) -> 0
Z33: =SUM(X33,V33,T33,R33,P33,N33,L33,J33,H33,F33,D33,B33) -> 0 | AA33: =SUM(C33,E33,G33,I33,K33,M33,O33,Q33,S33,U33,W33,Y33) -> 0
Z34: =SUM(X34,V34,T34,R34,P34,N34,L34,J34,H34,F34,D34,B34) -> 0 | AA34: =SUM(C34,E34,G34,I34,K34,M34,O34,Q34,S34,U34,W34,Y34) -> 0
Z35: =SUM(X35,V35,T35,R35,P35,N35,L35,J35,H35,F35,D35,B35) -> 0 | AA35: =SUM(C35,E35,G35,I35,K35,M35,O35,Q35,S35,U35,W35,Y35) -> 0
Z36: =SUM(X36,V36,T36,R36,P36,N36,L36,J36,H36,F36,D36,B36) -> 0 | AA36: =SUM(C36,E36,G36,I36,K36,M36,O36,Q36,S36,U36,W36,Y36) -> 0
Z37: =SUM(X37,V37,T37,R37,P37,N37,L37,J37,H37,F37,D37,B37) -> 0 | AA37: =SUM(C37,E37,G37,I37,K37,M37,O37,Q37,S37,U37,W37,Y37) -> 0
Z38: =SUM(X38,V38,T38,R38,P38,N38,L38,J38,H38,F38,D38,B38) -> 0 | AA38: =SUM(C38,E38,G38,I38,K38,M38,O38,Q38,S38,U38,W38,Y38) -> 0
Z39: =SUM(X39,V39,T39,R39,P39,N39,L39,J39,H39,F39,D39,B39) -> 0 | AA39: =SUM(C39,E39,G39,I39,K39,M39,O39,Q39,S39,U39,W39,Y39) -> 0
Z40: =SUM(X40,V40,T40,R40,P40,N40,L40,J40,H40,F40,D40,B40) -> 0 | AA40: =SUM(C40,E40,G40,I40,K40,M40,O40,Q40,S40,U40,W40,Y40) -> 0
Z41: =SUM(X41,V41,T41,R41,P41,N41,L41,J41,H41,F41,D41,B41) -> 0 | AA41: =SUM(C41,E41,G41,I41,K41,M41,O41,Q41,S41,U41,W41,Y41) -> 0
AA42: =SUM(AA30:AA41) -> 955.13579 | AB42: TOTALE TEP/ANNO ENERGIA
A43: 1.4. Combustibili
A45: Tabella 1.4.1. Consumo di combustibili
...

Sheet EMISSIONI IN ARIA
A2: 1 - COMPONENTI AMBIENTALI
A4: 1.5. Emissioni in aria
A6: Tabella 1.5.1. Punti di emissione (dati fisici)
A7: Punto di emissione | B7: giorni/anno di funzionamento del camino | C7: ore/giorno di funzionamento del camino
A8: 1 - Prepulitura | B8: 250 | C8: 10
A9: 2 - Lavorazione materiale separato dalla prepulitura | B9: 300 | C9: 7
A10: 3 - Pulitura | B10: 300 | C10: 24
A11: 4 - Pulitura | B11: 300 | C11: 24
A12: 5 - Trasporto pneumatico grano al molino | B12: 300 | C12: 24
A13: 6 - Trasporto pneumatico grano al molino | B13: 300 | C13: 24
A14: 7 - semolatrici | B14: 300 | C14: 24
A15: 8 - essiccazione farine | B15: 300 | C15: 24
A16: 9 - Raffreddamento farine | B16: 300 | C16: 24
A17: 10 - Caldaia produzione vapore | B17: 300 | C17: 24
A18: 11 - Aspirazione silos farina | B18: 300 | C18: 24
A19: 13 - Cubettatrice | B19: 300 | C19: 24
... A23: 18 - Carico rapido cisterna sfarinati | B23: 300 | C23: 10
A24: 19 - Carico rapido cisterna sfarinati
A25: 20 - Carico rapido cisterna sfarinati
A26: 21 - Carico rapido cisterna sfarinati
A29: Tabella 1.5.2. inquinanti monitorati | D29: Analisi del 05/11/2024 RdP n. 2310319-002-003-004-005-006-007-008--009-010-011-012-013-018 | J29: Analisi del 06/11/2024 RdP n. 2310319-014-015-016-017-019
A30: Punto di emissione | B30: Parametri monitorati | C30: Concentrazione limite da normativa o autorizzata in AIA [mg/Nm3] | D30: Portata (Nm3/h) | E30: Flusso di massa | F30: U.M. | G30: Concentrazioine | H30: U.M. | I30: Discostamento % dal valore limite di emissione | J30: Portata (Nm3/h) | K30: Flusso di massa | L30: U.M. | M30: Concentrazioine | N30: U.M. | O30: Discostamento % dal valore limite di emissione
A31: 1 - Prepulitura | B31: Polveri | C31: 5 | D31: 17400 | E31: =($D$31*G31*$B$8*$C$8)/(1000000) -> 41.325 | F31: kg/anno | G31: 0.95 | H31: mg/Nm3 | I31: =(G31/C31)*100 -> 19 | K31: =($J$31*M31*$B$8*$C$8)/(1000000) -> 0 | L31: kg/anno | N31: mg/Nm3 | O31: =(M31/C31)*100 -> 0
E32: =($J$31*G32*$B$8*$C$8)/(1000000) -> 0 | F32: kg/anno | H32: mg/Nm3 | I32: =(G32/#REF!)*100 -> #REF! | K32: =($J$31*M32*$B$8*$C$8)/(1000000) -> 0 | L32: kg/anno | N32: mg/Nm3 | O32: =(M32/C32)*100 -> #DIV/0!
E33: =($J$31*G33*$B$8*$C$8)/(1000000) -> 0 | F33: kg/anno | H33: mg/Nm3 | I33: =(G33/#REF!)*100 -> #REF! | K33: =($J$31*M33*$B$8*$C$8)/(1000000) -> 0 | L33: kg/anno | N33: mg/Nm3 | O33: =(M33/C33)*100 -> #DIV/0!
E34: =($J$31*G34*$B$8*$C$8)/(1000000) -> 0 | F34: kg/anno | H34: mg/Nm3 | I34: =(G34/#REF!)*100 -> #REF! | K34: =($J$31*M34*$B$8*$C$8)/(1000000) -> 0 | L34: kg/anno | N34: mg/Nm3 | O34: =(M34/C34)*100 -> #DIV/0!
E35: =($J$31*G35*$B$8*$C$8)/(1000000) -> 0 | F35: kg/anno | H35: mg/Nm3 | I35: =(G35/#REF!)*100 -> #REF! | K35: =($J$31*M35*$B$8*$C$8)/(1000000) -> 0 | L35: kg/anno | N35: mg/Nm3 | O35: =(M35/C35)*100 -> #DIV/0!
E36: =($J$31*G36*$B$8*$C$8)/(1000000) -> 0 | F36: kg/anno | H36: mg/Nm3 | I36: =(G36/#REF!)*100 -> #REF! | K36: =($J$31*M36*$B$8*$C$8)/(1000000) -> 0 | L36: kg/anno | N36: mg/Nm3 | O36: =(M36/C36)*100 -> #DIV/0!
A37: 2 - Lavorazione materiale separato dalla prepulitura | B37: Polveri | C37: 5 | D37: 2070 | E37: =($D$37*G37*$B$9*$C$9)/(1000000) -> 0.52164 | F37: kg/anno | G37: 0.12 | H37: mg/Nm3 | I37: =(G37/C37)*100 -> 2.4 | K37: =($J$37*M37*$B$9*$C$9)/(1000000) -> 0 | L37: kg/anno | N37: mg/Nm3 | O37: =(M37/C37)*100 -> 0
E38: =($J$37*G38*$B$8*$C$8)/(1000000) -> 0 | F38: kg/anno | H38: mg/Nm3 | I38: =(G38/#REF!)*100 -> #REF! | K38: =($J$37*M38*$B$8*$C$8)/(1000000) -> 0 | L38: kg/anno | N38: mg/Nm3 | O38: =(M38/C38)*100 -> #DIV/0!
E39: =($J$37*G39*$B$8*$C$8)/(1000000) -> 0 | F39: kg/anno | H39: mg/Nm3 | I39: =(G39/#REF!)*100 -> #REF! | K39: =($J$37*M39*$B$8*$C$8)/(1000000) -> 0 | L39: kg/anno | N39: mg/Nm3 | O39: =(M39/C39)*100 -> #DIV/0!
E40: =($J$37*G40*$B$8*$C$8)/(1000000) -> 0 | F40: kg/anno | H40: mg/Nm3 | I40: =(G40/#REF!)*100 -> #REF! | K40: =($J$37*M40*$B$8*$C$8)/(1000000) -> 0 | L40: kg/anno | N40: mg/Nm3 | O40: =(M40/C40)*100 -> #DIV/0!
E41: =($J$37*G41*$B$8*$C$8)/(1000000) -> 0 | F41: kg/anno | H41: mg/Nm3 | I41: =(G41/#REF!)*100 -> #REF! | K41: =($J$37*M41*$B$8*$C$8)/(1000000) -> 0 | L41: kg/anno | N41: mg/Nm3 | O41: =(M41/C41)*100 -> #DIV/0!
E42: =($J$37*G42*$B$8*$C$8)/(1000000) -> 0 | F42: kg/anno | H42: mg/Nm3 | I42: =(G42/#REF!)*100 -> #REF! | K42: =($J$37*M42*$B$8*$C$8)/(1000000) -> 0 | L42: kg/anno | N42: mg/Nm3 | O42: =(M42/C42)*100 -> #DIV/0!
A43: 3 - Pulitura | B43: Polveri | C43: 5 | D43: 24200 | E43: =($D$43*G43*$B$10*$C$10)/(1000000) -> 116.7408 | F43: kg/anno | G43: 0.67 | H43: mg/Nm3 | I43: =(G43/C43)*100 -> 13.4 | K43: =($J$43*M43*$B$10*$C$10)/(1000000) -> 0 | L43: kg/anno | N43: mg/Nm3 | O43: =(M43/C43)*100 -> 0
E44: =($J$37*G44*$B$8*$C$8)/(1000000) -> 0 | F44: kg/anno | H44: mg/Nm3 | I44: =(G44/#REF!)*100 -> #REF! | K44: =($J$37*M44*$B$8*$C$8)/(1000000) -> 0 | L44: kg/anno | N44: mg/Nm3 | O44: =(M44/C44)*100 -> #DIV/0!
E45: =($J$37*G45*$B$8*$C$8)/(1000000) -> 0 | F45: kg/anno | H45: mg/Nm3 | I45: =(G45/#REF!)*100 -> #REF! | K45: =($J$37*M45*$B$8*$C$8)/(1000000) -> 0 | L45: kg/anno | N45: mg/Nm3 | O45: =(M45/C45)*100 -> #DIV/0!
E46: =($J$37*G46*$B$8*$C$8)/(1000000) -> 0 | F46: kg/anno | H46: mg/Nm3 | I46: =(G46/#REF!)*100 -> #REF! | K46: =($J$37*M46*$B$8*$C$8)/(1000000) -> 0 | L46: kg/anno | N46: mg/Nm3 | O46: =(M46/C46)*100 -> #DIV/0!
E47: =($J$37*G47*$B$8*$C$8)/(1000000) -> 0 | F47: kg/anno | H47: mg/Nm3 | I47: =(G47/#REF!)*100 -> #REF! | K47: =($J$37*M47*$B$8*$C$8)/(1000000) -> 0 | L47: kg/anno | N47: mg/Nm3 | O47: =(M47/C47)*100 -> #DIV/0!
E48: =($J$37*G48*$B$8*$C$8)/(1000000) -> 0 | F48: kg/anno | H48: mg/Nm3 | I48: =(G48/#REF!)*100 -> #REF! | K48: =($J$37*M48*$B$8*$C$8)/(1000000) -> 0 | L48: kg/anno | N48: mg/Nm3 | O48: =(M48/C48)*100 -> #DIV/0!
...

Sheet EMISSIONI IN ACQUA
A2: 1 - COMPONENTI AMBIENTALI
A4: 1.6. Emissioni in acqua
A6: Tabella 1.6.1. Punti di emissione
A7: Punto di emissione | B7: Durata emissione h/giorno | C7: Durata emissione gg/anno
A8: SF1 - Fase F8 servizi igienici spogliatoi | B8: variabile | C8: 365
A9: SF2 - Acque meteoriche | B9: variabile | C9: variabile
A12: Tabella 1.6.2. Inquinanti monitorati | D12: Analisi del 26/03/2024 RdP n. 24/000213869 DEL 15/04/2024 | J12: Analisi del 16/10/024 RdP n. 24/000655853 DEL 04/11/2024
A13: Punto emissione | B13: Inquinanti | C13: Concentrazione limite da normantiva o autorizzata in AIA | D13: Portata (m3/d) | E13: Carico | F13: U.M. | G13: Concentrazione | H13: U.M. | I13: Discostamento % dal valore limite di emissione | J13: Portata (m3/d) | K13: Carico | L13: U.M. | M13: Concentrazione | N13: U.M. | O13: Discostamento % dal valore limite di emissione
A14: SF2 - Acque meteoriche | B14: Ph | C14: 5,5-9,5 | E14: =($D$14*G14/1000000000) -> #VALUE! | F14: [kg/d] | G14: 7,10+-0,08 | I14: =(G14/$C14)*100 -> #VALUE! | K14: =($J$14*M14/1000000000) -> #VALUE! | L14: [kg/d] | M14: 6,84+-0,08 | O14: =(M14/$C14)*100 -> #VALUE!
B15: Idrocarburi Totali | C15: <= 5 | E15: =($D$14*G15/1000000000) -> #VALUE! | F15: [kg/d] | G15: <RL | H15: mg/l | I15: =(G15/$C15)*100 -> #VALUE! | K15: =($J$14*M15/1000000000) -> #VALUE! | L15: [kg/d] | M15: <RL | N15: mg/l | O15: =(M15/$C15)*100 -> #VALUE!
B16: SST | C16: <= 80 | E16: =($D$14*G16/1000000000) -> #VALUE! | F16: [kg/d] | G16: <RL | H16: mg/l | I16: =(G16/$C16)*100 -> #VALUE! | K16: =($J$14*M16/1000000000) -> #VALUE! | L16: [kg/d] | M16: <RL | N16: mg/l | O16: =(M16/$C16)*100 -> #VALUE!
B17: COD | C17: <= 160 | E17: =($D$14*G17/1000000000) -> #VALUE! | F17: [kg/d] | G17: 32,8+-2,8 | H17: mg/l | I17: =(G17/$C17)*100 -> #VALUE! | K17: =($J$14*M17/1000000000) -> #VALUE! | L17: [kg/d] | M17: 34,2+-2,9 | N17: mg/l | O17: =(M17/$C17)*100 -> #VALUE!
B18: BOD 5 | C18: <= 40 | E18: =($D$14*G18/1000000000) -> #VALUE! | F18: [kg/d] | G18: 8,0+-3,4 | H18: mg/l | I18: =(G18/$C18)*100 -> #VALUE! | K18: =($J$14*M18/1000000000) -> #VALUE! | L18: [kg/d] | M18: 7,0+-3,4 | N18: mg/l | O18: =(M18/$C18)*100 -> #VALUE!
E19: =($D$14*G19/1000000000) -> 0 | F19: [kg/d] | I19: =(G19/$C19)*100 -> #DIV/0! | K19: =($J$14*M19/1000000000) -> 0 | L19: [kg/d] | N19: mg/l | O19: =(M19/$C19)*100 -> #DIV/0!

Sheet RUMORE
A1: 1 - COMPONENTI AMBIENTALI
A3: 1.7. Impatto acustico
A5: E' previsto il monitoraggio dellimpatto acustico nel PMC? (SI/NO) | D5: SI
A6: Se SI, è stato eseguito il monitoraggio durante l'anno di riferimento (SI/NO)? | D6: SI
A8: Tabella 1.7.1. Rumore
A9: Valutazione n. | B9: Condizioni di funzionamento degli impianti | C9: Parametro valutato | D9: Valore riscontrato | E9: UM | F9: Note (*)
A10: 1D | B10: nornale | C10: La | D10: 42.5 | E10: db (A)
A11: 2D | B11: nornale | C11: La | D11: 45 | E11: db (A)
A12: 3D | B12: nornale | C12: La | D12: 38 | E12: db (A)
A13: 4D | B13: nornale | C13: La | D13: 41 | E13: db (A)
A14: 1N | B14: nornale | C14: La | D14: 40.5 | E14: db (A)
A15: 2N | B15: nornale | C15: La | D15: 42.5 | E15: db (A)
A16: 3N | B16: nornale | C16: La | D16: 39 | E16: db (A)
A17: 4N | B17: nornale | C17: La | D17: 37 | E17: db (A)
A19: (*) nel caso in cui le misure non siano presso il ricettore indicare l’algoritmo utilizzato per risalire dalla misura al livello sonoro presso il ricettore.

Sheet RIFIUTI
A2: 1 - COMPONENTI AMBIENTALI
A4: 1.8 - Rifiuti
A6: Tabella 1.8.1 - Rifiuti in ingresso
A7: E' prevista l'utilizzo di rifiuti nel ciclo produttivo? (SI/NO) | D7: NO
A9: Rifiuti | B9: Codice CER | C9: Recupero (codice) | R9: U.M.
D10: GENNAIO | E10: FEBBRAIO | F10: MARZO | G10: APRILE | H10: APRILE | I10: MAGGIO | J10: GIUGNO | K10: LUGLIO | L10: AGOSTO | M10: SETTEMBRE | N10: OTTOBRE | O10: NOVEMBRE | P10: DICEMBRE | Q10: TOTALE ANNO
A11: / | B11: / | C11: / | Q11: =SUM(D11:P11) -> 0
A12: / | B12: / | C12: / | Q12: =SUM(D12:P12) -> 0
A13: / | B13: / | C13: / | Q13: =SUM(D13:P13) -> 0
A14: / | B14: / | C14: / | Q14: =SUM(D14:P14) -> 0
A15: / | B15: / | C15: / | Q15: =SUM(D15:P15) -> 0
A16: / | B16: / | C16: / | Q16: =SUM(D16:P16) -> 0
A17: / | B17: / | C17: / | Q17: =SUM(D17:P17) -> 0
Q18: =SUM(Q11:Q17) -> 0
A19: Tabella 1.8.2 - Rifiuti prodotti
A20: Rifiuti prodotti | B20: Codice CER | C20: Smaltimento (codice) | D20: Recupero (codice) | S20: U.M.
E21: GENNAIO | F21: FEBBRAIO | G21: MARZO | H21: MARZO | I21: APRILE | J21: MAGGIO | K21: GIUGNO | L21: LUGLIO | M21: AGOSTO | N21: SETTEMBRE | O21: OTTOBRE | P21: NOVEMBRE | Q21: DICEMBRE | R21: TOTALE ANNO
A22: Scarti inutilizzabili per il consumo o la trasformazione | B22: 020304 | D22: R13 | E22: 0.2 | F22: 0.4 | H22: 0.2 | I22: 0.3 | J22: 0.5 | L22: 13.9 | M22: 1.1 | N22: 0.2 | O22: 0.2 | P22: 0.2 | Q22: 2 | R22: =SUM(E22:Q22) -> 19.2 | S22: t
A23: Acido cloridrico | B23: 060102* | C23: D14 | R23: =SUM(E23:Q23) -> 0 | S23: t
A24: Soluzioni acquose di lavaggio ed acque madri | B24: 070101* | C24: D15 | H24: 0.005 | P24: 0.016 | R24: =SUM(E24:Q24) -> 0.021 | S24: t
A25: Toner esauriti | B25: 080318 | D25: R13 | E25: 0.03 | F25: 0.025 | H25: 0.03 | I25: 0.03 | J25: 0.01 | K25: 0.015 | L25: 0.04 | M25: 0.015 | N25: 0.025 | O25: 0.025 | P25: 0.09 | Q25: 0.065 | R25: =SUM(E25:Q25) -> 0.4 | S25: t
A26: Rifiuti liquidi acquosi contenenti sigillanti diversi da 080415 | B26: 080416 | C26: D09 | E26: 1 | F26: 1 | H26: 1 | I26: 1 | K26: 1 | L26: 1 | M26: 1 | N26: 0.92 | P26: 1 | Q26: 1 | R26: =SUM(E26:Q26) -> 9.92 | S26: t
A27: Scarti di olio | B27: 130205* | D27: R13 | F27: 0.1 | P27: 0.1 | R27: =SUM(E27:Q27) -> 0.2 | S27: t
A28: Olio diatermico | B28: 130307* | D28: R13 | R28: =SUM(E28:Q28) -> 0 | S28: t
A29: Acque oleose | B29: 130507* | D29: R13 | F29: 0.1 | H29: 0.1 | L29: 0.1 | P29: 0.1 | Q29: 0.1 | R29: =SUM(E29:Q29) -> 0.5 | S29: t
A30: altri solventi e miscele di solventi | B30: 140603* | D30: R13 | R30: =SUM(E30:Q30) -> 0 | S30: t
A31: Imballaggi di carta e cartone | B31: 150101 | D31: R13 | E31: 6.3 | F31: 4.5 | H31: 5 | I31: 7.14 | J31: 4.3 | K31: 3.5 | L31: 4.1 | M31: 4.14 | N31: 4.16 | O31: 7.88 | P31: 7.28 | Q31: 6.06 | R31: =SUM(E31:Q31) -> 64.36 | S31: t
A32: imballaggi di plastica | B32: 150102 | D32: R13 | E32: 0.3 | F32: 0.74 | H32: 1.12 | I32: 0.34 | J32: 0.72 | K32: 0.2 | L32: 0.38 | M32: 0.15 | N32: 0.47 | O32: 0.6 | P32: 0.48 | Q32: 0.04 | R32: =SUM(E32:Q32) -> 5.54 | S32: t
A33: Imballaggi in legno | B33: 150103 | D33: R13 | R33: =SUM(E33:Q33) -> 0 | S33: t
A34: Imballaggi in materiali misti | B34: 150106 | D34: R12 | E34: 0.25 | F34: 0.3 | H34: 0.15 | I34: 0.3 | J34: 0.96 | K34: 0.2 | L34: 0.2 | M34: 0.1 | N34: 0.1 | O34: 0.3 | P34: 0.24 | R34: =SUM(E34:Q34) -> 3.1 | S34: t
A35: Imballaggi contaminati da sostanze pericolose | B35: 150110* | D35: R13 | E35: 0.01 | F35: 0.01 | I35: 0.005 | L35: 0.005 | M35: 0.01 | O35: 0.01 | Q35: 0.01 | R35: =SUM(E35:Q35) -> 0.06 | S35: t
A36: Imballaggi metallici | B36: 150111* | D36: R13 | H36: 0.001 | K36: 0.002 | L36: 0.001 | P36: 0.02 | Q36: 0.016 | R36: =SUM(E36:Q36) -> 0.04 | S36: t
A37: Ass. e mat. filtranti contaminati da sost. Pericolose | B37: 150202* | D37: R13 | E37: 0.01 | F37: 0.02 | H37: 0.01 | I37: 0.01 | J37: 0.05 | K37: 0.02 | L37: 0.01 | M37: 0.02 | O37: 0.008 | R37: =SUM(E37:Q37) -> 0.158 | S37: t
A38: Ass. e mat. filtranti diversi da 150202 | B38: 150203 | D38: R12 | E38: 0.1 | I38: 0.15 | J38: 0.15 | K38: 0.1 | L38: 0.05 | M38: 0.1 | N38: 0.08 | O38: 0.19 | P38: 0.22 | R38: =SUM(E38:Q38) -> 1.14 | S38: t
A39: Apparecchiature fuori uso con comp. pericolosi | B39: 160213* | D39: R13 | R39: =SUM(E39:Q39) -> 0 | S39: t
A40: Apparecchiature fuori diverse da 160213 | B40: 160214 | D40: R13 | R40: =SUM(E40:Q40) -> 0 | S40: t
A41: Componenti pericolosi rimossi da apparecchiature fuori uso | B41: 160215* | D41: R13 | R41: =SUM(E41:Q41) -> 0 | S41: t
A42: Componenti rimossi da apparecchiature fuori uso | B42: 160216 | D42: R13 | R42: =SUM(E42:Q42) -> 0 | S42: t
A43: Rifiuti inorganici, contenenti sostanze pericolose | B43: 160303* | C43: D15 | R43: =SUM(E43:Q43) -> 0 | S43: t
A44: Gas in contenitori a pressione, diversi da quelli di cui alla voce 16 05 04 | B44: 160505 | D44: R13 | R44: =SUM(E44:Q44) -> 0 | S44: t
...

Sheet SUOLO E SOTTOSUOLO
A1: 1 - COMPONENTI AMBIENTALI
A3: 1.9 – Suolo e sottosuolo
A5: Tabella 1.9.1 – Acque di falda
A7: E' previsto il controllo analitico delle acque di falda? (SI/NO) | D7: NO
A9: PROFONDITA' DEL PUNTO DI PRELIEVO | B9: /
A11: Punto di misura/piezometro | B11: Parametro / inquinante | C11: Concentrazione limite da normativa [mg/l] | D11: Analisi del gg/mm/aaaa RdP n. ______ | G11: Analisi del gg/mm/aaaa RdP n. ______
B12: inquinante | C12: Concentrazione limite da normantiva o autorizzata in AIA [mg/l] | D12: Concentrazioine | E12: U.M. | F12: Discostamento % dal valore limite di emissione | G12: Concentrazioine | H12: U.M. | I12: Discostamento % dal valore limite di emissione
F13: =(D13/C13)*100 -> #DIV/0! | I13: =(G13/C13)*100 -> #DIV/0!
F14: =(D14/C14)*100 -> #DIV/0! | I14: =(G14/C14)*100 -> #DIV/0!
F15: =(D15/C15)*100 -> #DIV/0! | I15: =(G15/C15)*100 -> #DIV/0!
F16: =(D16/C16)*100 -> #DIV/0! | I16: =(G16/C16)*100 -> #DIV/0!
F17: =(D17/C17)*100 -> #DIV/0! | I17: =(G17/C17)*100 -> #DIV/0!
F18: =(D18/C18)*100 -> #DIV/0! | I18: =(G18/C18)*100 -> #DIV/0!
F19: =(D19/C19)*100 -> #DIV/0! | I19: =(G19/C19)*100 -> #DIV/0!
F20: =(D20/C20)*100 -> #DIV/0! | I20: =(G20/C20)*100 -> #DIV/0!
F21: =(D21/C21)*100 -> #DIV/0! | I21: =(G21/C21)*100 -> #DIV/0!
F22: =(D22/C22)*100 -> #DIV/0! | I22: =(G22/C22)*100 -> #DIV/0!
F23: =(D23/C23)*100 -> #DIV/0! | I23: =(G23/C23)*100 -> #DIV/0!
F24: =(D24/C24)*100 -> #DIV/0! | I24: =(G24/C24)*100 -> #DIV/0!
... F26: =(D26/C26)*100 -> #DIV/0! | I26: =(G26/C26)*100 -> #DIV/0!

Sheet GESTIONALE
A2: 2- GESTIONE DELL'IMPIANTO
A4: 2.1 Controllo fasi critiche, manutenzioni, stoccaggi
A6: Tabella 2.1.1 - Sistemi di controllo delle fasi critiche del processo
A8: Fase di Produzione | B8: Attività di controllo/Parametri di Controllo | C8: UM | D8: Risultato del controllo | E8: Data del controllo | F8: Commenti
A16: Tabella 2.1.2 - Interventi di manutenzione ordinaria (e straordinaria) sugli impianti di abbattimento degli inquinanti (ed eventuali fasi critiche del processo)
A18: Macchinario | B18: Tipo di intervento | C18: Data intervento | D18: Descrivere le criticità riscontrate | E18: Tipo di manutenzione (Ordinaria o Straordinaria)
A24: Tabella 2.1.3 - Sistemi di trattamento fumi: controllo del processo
A26: Punto emissione | B26: Sistema di abbattimento | C26: Parametri di controllo del processo di abbattimento | D26: Risultato del controllo | E26: UM | F26: Data del controllo
A32: Tabella 2.1.4- Sistemi di depurazione: controllo del processo
A34: Punto emissione | B34: Sistema di trattamento (stadio di trattamento) | C34: Parametri di controllo del processo di trattamento | D34: Risultato del controllo | E34: UM | F34: Data del controllo
A40: Tabella 2.1.5 - Aree di stoccaggio (vasche, serbatoi, bacini di contenimento etc.)
A42: Tipologia di stoccaggio e localizzazione | B42: Criticità/Parametro | C42: Verifica effettuata | D42: Data controllo | E42: Descrivere le criticità riscontrate.

Sheet INDICATORI DI PRESTAZIONE
A2: 3 – INDICATORI DI PRESTAZIONE
A5: Tabella 3.1. Monitoraggio degli indicatori di performance
A7: Indicatore a sua descrizione | B7: Valore | C7: UM
A8: Materie prime
A12: Consumo specifico di energia (consumo di energia finale/tasso di attività) | B12: =((('ACQUA ED ENERGIA'!Z30+'ACQUA ED ENERGIA'!Z31)/1000)+('ACQUA ED ENERGIA'!AA51*10.69/1000))/('MATERIE PRIME'!N86+'MATERIE PRIME'!N87+'MATERIE PRIME'!N88) -> 0.10671559 | C12: MWh/t
A13: Energia elettrica da rete esterna vs. grano macinato | B13: ='ACQUA ED ENERGIA'!Z30/'MATERIE PRIME'!N11 -> 101.0619 | C13: Kwh/t
A14: Energia elettrica autoprodotta vs. grano macinato | B14: ='ACQUA ED ENERGIA'!Z31/'MATERIE PRIME'!N11 -> 7.5269607 | C14: Kwh/t
A15: Emissioni
A16: Polveri emesse / grano macinato | B16: =('EMISSIONI IN ARIA'!E31+'EMISSIONI IN ARIA'!E37+'EMISSIONI IN ARIA'!E43+'EMISSIONI IN ARIA'!E49+'EMISSIONI IN ARIA'!E55+'EMISSIONI IN ARIA'!E61+'EMISSIONI IN ARIA'!E67+'EMISSIONI IN ARIA'!E73+'EMISSIONI IN ARIA'!E79+'EMISSIONI IN ARIA'!E91+'EMISSIONI IN ARIA'!E97+'EMISSIONI IN ARIA'!E103+'EMISSIONI IN ARIA'!E109+'EMISSIONI IN ARIA'!K115+'EMISSIONI IN ARIA'!K121+'EMISSIONI IN ARIA'!K127+'EMISSIONI IN ARIA'!K133)/('MATERIE PRIME'!N11) -> 0.0057966409 | C16: Kg/t
A18: Consumi idrici
A19: Acqua utilizzata in bagnatura / farina prodotta | B19: ='ACQUA ED ENERGIA'!N9*1000/'MATERIE PRIME'!N86 -> 61.086418 | C19: l/t
A20: Acqua utilizzata in bagnatura / grano macinato | B20: ='ACQUA ED ENERGIA'!N9*1000/'MATERIE PRIME'!N11 -> 57.519922 | C20: l/t
A24: Rifiuti (sottoprodotti)
A25: Rifiuti totali (P e NP) vs. grano macinato | B25: =(RIFIUTI!R62*1000)/'MATERIE PRIME'!N11 -> 1.964211 | C25: Kg/t
A26: Rifiuti non pericolosi vs. grano macinato | B26: =((RIFIUTI!R22+RIFIUTI!R25+RIFIUTI!R26+RIFIUTI!R31+RIFIUTI!R32+RIFIUTI!R33+RIFIUTI!R34+RIFIUTI!R38+RIFIUTI!R40+RIFIUTI!R42+RIFIUTI!R44+RIFIUTI!R47+RIFIUTI!R48+RIFIUTI!R50+RIFIUTI!R51+RIFIUTI!R52+RIFIUTI!R53+RIFIUTI!R55)*1000)/'MATERIE PRIME'!N11 -> 1.9411371 | C26: Kg/t
A27: Rifiuti pericolosi vs. grano macinato | B27: =((RIFIUTI!R23+RIFIUTI!R24+RIFIUTI!R27+RIFIUTI!R28+RIFIUTI!R29+RIFIUTI!R30+RIFIUTI!R35+RIFIUTI!R36+RIFIUTI!R37+RIFIUTI!R39+RIFIUTI!R41+RIFIUTI!R43+RIFIUTI!R45+RIFIUTI!R46+RIFIUTI!R49+RIFIUTI!R54)*1000)/'MATERIE PRIME'!N11 -> 0.023073894 | C27: Kg/t
A28: % rifiuti a recupero vs. rifiuti totali | B28: =((RIFIUTI!R22+RIFIUTI!R24+RIFIUTI!R27+RIFIUTI!R28+RIFIUTI!R29+RIFIUTI!R30+RIFIUTI!R31+RIFIUTI!R32+RIFIUTI!R33+RIFIUTI!R34+RIFIUTI!R35+RIFIUTI!R36+RIFIUTI!R37+RIFIUTI!R38+RIFIUTI!R39+RIFIUTI!R40+RIFIUTI!R41+RIFIUTI!R42+RIFIUTI!R44+RIFIUTI!R47+RIFIUTI!R48+RIFIUTI!R50+RIFIUTI!R53+RIFIUTI!R54)*100)/RIFIUTI!R62 -> 89.706321 | C28: %
A29: Scarti inutilizzabili per il consumo (CER 020304) / farina prodotta | B29: =(RIFIUTI!R22*1000)/'MATERIE PRIME'!N86 -> 0.37340313 | C29: Kg/t
A30: Imballaggi carta e cartone (CER 150101) / farina prodotta | B30: =(RIFIUTI!R31*1000)/'MATERIE PRIME'!N86 -> 1.2516784 | C30: Kg/t
A31: Combustibili
A32: Consumo di metano vs. grano macinato | B32: ='ACQUA ED ENERGIA'!AA51/'MATERIE PRIME'!N11 -> 1.707003 | C32: m3/t
A33: Consumo di metano vs. farina prodotta | B33: ='ACQUA ED ENERGIA'!AA51/'MATERIE PRIME'!N86 -> 1.8128449 | C33: m3/t

Sheet ALTRE DICHIARAZIONI
A2: ALTRE DICHIARAZIONI

Sheet Foglio1
